Workbook

Sheet CRP
A1: Country | B1: Country code | C1: 2000 | D1: 2001 | E1: 2002 | F1: 2003 | G1: 2004 | H1: 2005 | I1: 2006 | J1: 2007 | K1: 2008 | L1: 2009 | M1: 2010 | N1: 2011 | O1: 2012 | P1: 2013 | Q1: 2014 | R1: 2015 | S1: 2016 | T1: 2017 | U1: 2018 | V1: 2019 | W1: 2020 | X1: 2021 | Y1: 2022 | Z1: 2023 | AA1: 2024 | AB1: 2025 | AC1: Country Risk Premium
A2: ERP | B2: ERP | C2: ='ERP2000'!E8*100 -> 5.51 | D2: ='ERP2001'!E8*100 -> 5.51 | E2: ='ERP2002'!E9*100 -> 4.51 | F2: ='ERP2003'!E9*100 -> 4.82 | G2: ='ERP2004'!E9*100 -> 4.84 | H2: ='ERP2005'!E9*100 -> 4.8 | I2: ='ERP2006'!E9*100 -> 4.91 | J2: ='ERP2007'!E9*100 -> 4.79 | K2: ='ERP2008'!E9*100 -> 5 | L2: ='ERP2009'!E9*100 -> 4.5 | M2: ='ERP2010'!E9*100 -> 5 | N2: ='ERP2011'!E9*100 -> 6 | O2: ='ERP2012'!E3*100 -> 5.8 | P2: ='ERP2013'!E3*100 -> 5 | Q2: ='ERP2014'!E3*100 -> 5.75 | R2: ='ERP2015'!E3*100 -> 6.25 | S2: ='ERP2016'!E3*100 -> 5.69 | T2: ='ERP2017'!E3*100 -> 5.08 | U2: ='ERP2018'!E3*100 -> 5.96 | V2: ='ERP2019'!E3*100 -> 5.2 | W2: ='ERP2020'!E3*100 -> 4.72 | X2: ='ERP2021'!E3*100 -> 4.24 | Y2: ='ERP2022'!E3*100 -> 5.94 | Z2: ='ERP2023'!E3*100 -> 4.6 | AA2: ='ERP2024'!E3*100 -> 4.33 | AB2: ='ERP2025'!E3*100 -> 4.21 | AC2: CRP
A3: Abu Dhabi | B3: ABD | C3: =IFERROR(INDEX('ERP2000'!$A$18:$F$159,MATCH(CRP!$A3,'ERP2000'!$A$18:$A$159,0),MATCH($AC$1,'ERP2000'!$A$20:$F$20,0))*100, "") | D3: =IFERROR(INDEX('ERP2001'!$A$18:$F$159,MATCH(CRP!$A3,'ERP2001'!$A$18:$A$159,0),MATCH($AC$1,'ERP2001'!$A$20:$F$20,0))*100, "") | E3: =IFERROR(INDEX('ERP2002'!$A$18:$F$159,MATCH(CRP!$A3,'ERP2002'!$A$18:$A$159,0),MATCH($AC$1,'ERP2002'!$A$21:$F$21,0))*100, "") | F3: =IFERROR(INDEX('ERP2003'!$A$18:$F$159,MATCH(CRP!$A3,'ERP2003'!$A$18:$A$159,0),MATCH($AC$1,'ERP2003'!$A$21:$F$21,0))*100, "") | G3: =IFERROR(INDEX('ERP2004'!$A$18:$F$159,MATCH(CRP!$A3,'ERP2004'!$A$18:$A$159,0),MATCH($AC$1,'ERP2004'!$A$21:$F$21,0))*100, "") | H3: =IFERROR(INDEX('ERP2005'!$A$18:$F$159,MATCH(CRP!$A3,'ERP2005'!$A$18:$A$159,0),MATCH($AC$1,'ERP2005'!$A$21:$F$21,0))*100, "") | I3: =IFERROR(INDEX('ERP2006'!$A$18:$F$159,MATCH(CRP!$A3,'ERP2006'!$A$18:$A$159,0),MATCH($AC$1,'ERP2006'!$A$21:$F$21,0))*100, "") | J3: =IFERROR(INDEX('ERP2007'!$A$18:$F$159,MATCH(CRP!$A3,'ERP2007'!$A$18:$A$159,0),MATCH($AC$1,'ERP2007'!$A$21:$F$21,0))*100, "") | K3: =IFERROR(INDEX('ERP2008'!$A$18:$F$159,MATCH(CRP!$A3,'ERP2008'!$A$18:$A$159,0),MATCH($AC$1,'ERP2008'!$A$21:$F$21,0))*100, "") | L3: =IFERROR(INDEX('ERP2009'!$A$18:$F$159,MATCH(CRP!$A3,'ERP2009'!$A$18:$A$159,0),MATCH($AC$1,'ERP2009'!$A$18:$F$18,0))*100, "") | M3: =IFERROR(INDEX('ERP2010'!$A$18:$F$159,MATCH(CRP!$A3,'ERP2010'!$A$18:$A$159,0),MATCH($AC$1,'ERP2010'!$A$18:$F$18,0))*100, "") | N3: =IFERROR(INDEX('ERP2011'!$A$18:$F$159,MATCH(CRP!$A3,'ERP2011'!$A$18:$A$159,0),MATCH($AC$1,'ERP2011'!$A$18:$F$18,0))*100, "") | O3: =IFERROR(IFERROR(INDEX('ERP2012'!$A$8:$F$159,MATCH(CRP!$A3,'ERP2012'!$A$8:$A$159,0),MATCH($AC$1,'ERP2012'!$A$7:$F$7,0)),INDEX('ERP2012'!$A$160:$E$184,MATCH(CRP!$A3,'ERP2012'!$A$160:$A$184,0),MATCH($AC$2,'ERP2012'!$A$160:$E$160,0)))*100, "") | P3: =IFERROR(IFERROR(INDEX('ERP2013'!$A$8:$F$159,MATCH(CRP!$A3,'ERP2013'!$A$8:$A$159,0),MATCH($AC$1,'ERP2013'!$A$7:$F$7,0)),INDEX('ERP2013'!$A$160:$E$184,MATCH(CRP!$A3,'ERP2013'!$A$160:$A$184,0),MATCH($AC$2,'ERP2013'!$A$160:$E$160,0)))*100, "") -> 0.75 | Q3: =IFERROR(IFERROR(INDEX('ERP2014'!$A$8:$F$159,MATCH(CRP!$A3,'ERP2014'!$A$8:$A$159,0),MATCH($AC$1,'ERP2014'!$A$7:$F$7,0)),INDEX('ERP2014'!$A$160:$E$184,MATCH(CRP!$A3,'ERP2014'!$A$160:$A$184,0),MATCH($AC$2,'ERP2014'!$A$160:$E$160,0)))*100, "") -> 0.75 | R3: =IFERROR(IFERROR(INDEX('ERP2015'!$A$8:$F$159,MATCH(CRP!$A3,'ERP2015'!$A$8:$A$159,0),MATCH($AC$1,'ERP2015'!$A$7:$F$7,0)),INDEX('ERP2015'!$A$160:$E$184,MATCH(CRP!$A3,'ERP2015'!$A$160:$A$184,0),MATCH($AC$2,'ERP2015'!$A$160:$E$160,0)))*100, "") -> 0.784 | S3: =IFERROR(IFERROR(INDEX('ERP2016'!$A$8:$F$159,MATCH(CRP!$A3,'ERP2016'!$A$8:$A$159,0),MATCH($AC$1,'ERP2016'!$A$7:$F$7,0)),INDEX('ERP2016'!$A$160:$E$184,MATCH(CRP!$A3,'ERP2016'!$A$160:$A$184,0),MATCH($AC$2,'ERP2016'!$A$160:$E$160,0)))*100, "") -> 0.7053128 | T3: =IFERROR(IFERROR(INDEX('ERP2017'!$A$8:$F$159,MATCH(CRP!$A3,'ERP2017'!$A$8:$A$159,0),MATCH($AC$1,'ERP2017'!$A$7:$F$7,0)),INDEX('ERP2017'!$A$160:$E$190,MATCH(CRP!$A3,'ERP2017'!$A$160:$A$190,0),MATCH($AC$2,Table217[#Headers],0)))*100, "") -> 0.57201482 | U3: =IFERROR(IFERROR(INDEX('ERP2018'!$A$8:$F$159,MATCH(CRP!$A3,'ERP2018'!$A$8:$A$159,0),MATCH($AC$1,'ERP2018'!$A$7:$F$7,0)),INDEX('ERP2018'!$A$163:$E$190,MATCH(CRP!$A3,'ERP2018'!$A$163:$A$190,0),MATCH($AC$2,'ERP2018'!$A$163:$E$163,0)))*100, "") -> 0.6886858 | V3: =IFERROR(IFERROR(INDEX('ERP2019'!$A$8:$F$163,MATCH(CRP!$A3,'ERP2019'!$A$8:$A$163,0),MATCH($AC$1,'ERP2019'!$A$7:$F$7,0)),INDEX('ERP2019'!$A$165:$E$190,MATCH(CRP!$A3,'ERP2019'!$A$165:$A$190,0),MATCH($AC$2,'ERP2019'!$A$165:$E$165,0)))*100, "") -> 0.48935841 | W3: =IFERROR(INDEX('ERP2020'!$A$8:$F$165,MATCH(CRP!$A3,'ERP2020'!$A$8:$A$165,0),MATCH($AC$1,'ERP2020'!$A$7:$F$7,0)),INDEX('ERP2020'!$A$166:$E$190,MATCH(CRP!$A3,'ERP2020'!$A$166:$A$190,0),MATCH($AC$2,'ERP2020'!$A$166:$E$166,0)))*100 -> 0.48055029 | X3: =IFERROR(INDEX('ERP2021'!$A$8:$F$165,MATCH(CRP!$A3,'ERP2021'!$A$8:$A$165,0),MATCH($AC$1,'ERP2021'!$A$7:$F$7,0)),INDEX('ERP2021'!$A$166:$E$190,MATCH(CRP!$A3,'ERP2021'!$A$166:$A$190,0),MATCH($AC$2,'ERP2021'!$A$166:$E$166,0)))*100 -> 0.49069012 | Y3: =IFERROR(INDEX('ERP2022'!$A$8:$F$165,MATCH(CRP!$A3,'ERP2022'!$A$8:$A$165,0),MATCH($AC$1,'ERP2022'!$A$7:$F$7,0)),INDEX('ERP2022'!$A$166:$E$190,MATCH(CRP!$A3,'ERP2022'!$A$166:$A$190,0),MATCH($AC$2,'ERP2022'!$A$166:$E$166,0)))*100 -> 0.85200432 | Z3: =IFERROR(INDEX('ERP2023'!$A$8:$F$165,MATCH(CRP!$A3,'ERP2023'!$A$8:$A$165,0),MATCH($AC$1,'ERP2023'!$A$7:$F$7,0)),INDEX('ERP2023'!$A$165:$E$190,MATCH(CRP!$A3,'ERP2023'!$A$165:$A$190,0),MATCH($AC$2,'ERP2023'!$A$165:$E$165,0)))*100 -> 0.7219474 | AA3: =IFERROR(INDEX('ERP2024'!$A$8:$F$165,MATCH(CRP!$A3,'ERP2024'!$A$8:$A$165,0),MATCH($AC$1,'ERP2024'!$A$7:$F$7,0)),INDEX('ERP2024'!$A$166:$E$190,MATCH(CRP!$A3,'ERP2024'!$A$166:$A$190,0),MATCH($AC$2,'ERP2024'!$A$166:$E$166,0)))*100 -> 0.6587888 | AB3: =IFERROR(INDEX('ERP2025'!$A$8:$F$165,MATCH(CRP!$A3,'ERP2025'!$A$8:$A$165,0),MATCH($AC$1,'ERP2025'!$A$7:$F$7,0)),INDEX('ERP2024'!$A$166:$E$190,MATCH(CRP!$A3,'ERP2025'!$A$166:$A$190,0),MATCH($AC$2,'ERP2024'!$A$166:$E$166,0)))*100 -> 0.73024796
A4: Albania | B4: ALB | C4: =IFERROR(INDEX('ERP2000'!$A$18:$F$159,MATCH(CRP!$A4,'ERP2000'!$A$18:$A$159,0),MATCH($AC$1,'ERP2000'!$A$20:$F$20,0))*100, "") | D4: =IFERROR(INDEX('ERP2001'!$A$18:$F$159,MATCH(CRP!$A4,'ERP2001'!$A$18:$A$159,0),MATCH($AC$1,'ERP2001'!$A$20:$F$20,0))*100, "") | E4: =IFERROR(INDEX('ERP2002'!$A$18:$F$159,MATCH(CRP!$A4,'ERP2002'!$A$18:$A$159,0),MATCH($AC$1,'ERP2002'!$A$21:$F$21,0))*100, "") | F4: =IFERROR(INDEX('ERP2003'!$A$18:$F$159,MATCH(CRP!$A4,'ERP2003'!$A$18:$A$159,0),MATCH($AC$1,'ERP2003'!$A$21:$F$21,0))*100, "") | G4: =IFERROR(INDEX('ERP2004'!$A$18:$F$159,MATCH(CRP!$A4,'ERP2004'!$A$18:$A$159,0),MATCH($AC$1,'ERP2004'!$A$21:$F$21,0))*100, "") | H4: =IFERROR(INDEX('ERP2005'!$A$18:$F$159,MATCH(CRP!$A4,'ERP2005'!$A$18:$A$159,0),MATCH($AC$1,'ERP2005'!$A$21:$F$21,0))*100, "") | I4: =IFERROR(INDEX('ERP2006'!$A$18:$F$159,MATCH(CRP!$A4,'ERP2006'!$A$18:$A$159,0),MATCH($AC$1,'ERP2006'!$A$21:$F$21,0))*100, "") | J4: =IFERROR(INDEX('ERP2007'!$A$18:$F$159,MATCH(CRP!$A4,'ERP2007'!$A$18:$A$159,0),MATCH($AC$1,'ERP2007'!$A$21:$F$21,0))*100, "") -> 5.25 | K4: =IFERROR(INDEX('ERP2008'!$A$18:$F$159,MATCH(CRP!$A4,'ERP2008'!$A$18:$A$159,0),MATCH($AC$1,'ERP2008'!$A$21:$F$21,0))*100, "") -> 9.75 | L4: =IFERROR(INDEX('ERP2009'!$A$18:$F$159,MATCH(CRP!$A4,'ERP2009'!$A$18:$A$159,0),MATCH($AC$1,'ERP2009'!$A$18:$F$18,0))*100, "") -> 6.75 | M4: =IFERROR(INDEX('ERP2010'!$A$18:$F$159,MATCH(CRP!$A4,'ERP2010'!$A$18:$A$159,0),MATCH($AC$1,'ERP2010'!$A$18:$F$18,0))*100, "") -> 6 | N4: =IFERROR(INDEX('ERP2011'!$A$18:$F$159,MATCH(CRP!$A4,'ERP2011'!$A$18:$A$159,0),MATCH($AC$1,'ERP2011'!$A$18:$F$18,0))*100, "") -> 6 | O4: =IFERROR(IFERROR(INDEX('ERP2012'!$A$8:$F$159,MATCH(CRP!$A4,'ERP2012'!$A$8:$A$159,0),MATCH($AC$1,'ERP2012'!$A$7:$F$7,0)),INDEX('ERP2012'!$A$160:$E$184,MATCH(CRP!$A4,'ERP2012'!$A$160:$A$184,0),MATCH($AC$2,'ERP2012'!$A$160:$E$160,0)))*100, "") -> 6 | P4: =IFERROR(IFERROR(INDEX('ERP2013'!$A$8:$F$159,MATCH(CRP!$A4,'ERP2013'!$A$8:$A$159,0),MATCH($AC$1,'ERP2013'!$A$7:$F$7,0)),INDEX('ERP2013'!$A$160:$E$184,MATCH(CRP!$A4,'ERP2013'!$A$160:$A$184,0),MATCH($AC$2,'ERP2013'!$A$160:$E$160,0)))*100, "") -> 6.75 | Q4: =IFERROR(IFERROR(INDEX('ERP2014'!$A$8:$F$159,MATCH(CRP!$A4,'ERP2014'!$A$8:$A$159,0),MATCH($AC$1,'ERP2014'!$A$7:$F$7,0)),INDEX('ERP2014'!$A$160:$E$184,MATCH(CRP!$A4,'ERP2014'!$A$160:$A$184,0),MATCH($AC$2,'ERP2014'!$A$160:$E$160,0)))*100, "") -> 6.75 | R4: =IFERROR(IFERROR(INDEX('ERP2015'!$A$8:$F$159,MATCH(CRP!$A4,'ERP2015'!$A$8:$A$159,0),MATCH($AC$1,'ERP2015'!$A$7:$F$7,0)),INDEX('ERP2015'!$A$160:$E$184,MATCH(CRP!$A4,'ERP2015'!$A$160:$A$184,0),MATCH($AC$2,'ERP2015'!$A$160:$E$160,0)))*100, "") -> 7.07 | S4: =IFERROR(IFERROR(INDEX('ERP2016'!$A$8:$F$159,MATCH(CRP!$A4,'ERP2016'!$A$8:$A$159,0),MATCH($AC$1,'ERP2016'!$A$7:$F$7,0)),INDEX('ERP2016'!$A$160:$E$184,MATCH(CRP!$A4,'ERP2016'!$A$160:$A$184,0),MATCH($AC$2,'ERP2016'!$A$160:$E$160,0)))*100, "") -> 6.3991107 | T4: =IFERROR(IFERROR(INDEX('ERP2017'!$A$8:$F$159,MATCH(CRP!$A4,'ERP2017'!$A$8:$A$159,0),MATCH($AC$1,'ERP2017'!$A$7:$F$7,0)),INDEX('ERP2017'!$A$160:$E$190,MATCH(CRP!$A4,'ERP2017'!$A$160:$A$190,0),MATCH($AC$2,Table217[#Headers],0)))*100, "") -> 5.1897345 | U4: =IFERROR(IFERROR(INDEX('ERP2018'!$A$8:$F$159,MATCH(CRP!$A4,'ERP2018'!$A$8:$A$159,0),MATCH($AC$1,'ERP2018'!$A$7:$F$7,0)),INDEX('ERP2018'!$A$163:$E$190,MATCH(CRP!$A4,'ERP2018'!$A$163:$A$190,0),MATCH($AC$2,'ERP2018'!$A$163:$E$163,0)))*100, "") -> 6.2482584 | V4: =IFERROR(IFERROR(INDEX('ERP2019'!$A$8:$F$163,MATCH(CRP!$A4,'ERP2019'!$A$8:$A$163,0),MATCH($AC$1,'ERP2019'!$A$7:$F$7,0)),INDEX('ERP2019'!$A$165:$E$190,MATCH(CRP!$A4,'ERP2019'!$A$165:$A$190,0),MATCH($AC$2,'ERP2019'!$A$165:$E$165,0)))*100, "") -> 4.4398154 | W4: =IFERROR(INDEX('ERP2020'!$A$8:$F$165,MATCH(CRP!$A4,'ERP2020'!$A$8:$A$165,0),MATCH($AC$1,'ERP2020'!$A$7:$F$7,0)),INDEX('ERP2020'!$A$166:$E$190,MATCH(CRP!$A4,'ERP2020'!$A$166:$A$190,0),MATCH($AC$2,'ERP2020'!$A$166:$E$166,0)))*100 -> 4.3599017 | X4: =IFERROR(INDEX('ERP2021'!$A$8:$F$165,MATCH(CRP!$A4,'ERP2021'!$A$8:$A$165,0),MATCH($AC$1,'ERP2021'!$A$7:$F$7,0)),INDEX('ERP2021'!$A$166:$E$190,MATCH(CRP!$A4,'ERP2021'!$A$166:$A$190,0),MATCH($AC$2,'ERP2021'!$A$166:$E$166,0)))*100 -> 4.4518977 | Y4: =IFERROR(INDEX('ERP2022'!$A$8:$F$165,MATCH(CRP!$A4,'ERP2022'!$A$8:$A$165,0),MATCH($AC$1,'ERP2022'!$A$7:$F$7,0)),INDEX('ERP2022'!$A$166:$E$190,MATCH(CRP!$A4,'ERP2022'!$A$166:$A$190,0),MATCH($AC$2,'ERP2022'!$A$166:$E$166,0)))*100 -> 7.7694679 | Z4: =IFERROR(INDEX('ERP2023'!$A$8:$F$165,MATCH(CRP!$A4,'ERP2023'!$A$8:$A$165,0),MATCH($AC$1,'ERP2023'!$A$7:$F$7,0)),INDEX('ERP2023'!$A$165:$E$190,MATCH(CRP!$A4,'ERP2023'!$A$165:$A$190,0),MATCH($AC$2,'ERP2023'!$A$165:$E$165,0)))*100 -> 6.5834727 | AA4: =IFERROR(INDEX('ERP2024'!$A$8:$F$165,MATCH(CRP!$A4,'ERP2024'!$A$8:$A$165,0),MATCH($AC$1,'ERP2024'!$A$7:$F$7,0)),INDEX('ERP2024'!$A$166:$E$190,MATCH(CRP!$A4,'ERP2024'!$A$166:$A$190,0),MATCH($AC$2,'ERP2024'!$A$166:$E$166,0)))*100 -> 4.7997469 | AB4: =IFERROR(INDEX('ERP2025'!$A$8:$F$165,MATCH(CRP!$A4,'ERP2025'!$A$8:$A$165,0),MATCH($AC$1,'ERP2025'!$A$7:$F$7,0)),INDEX('ERP2024'!$A$166:$E$190,MATCH(CRP!$A4,'ERP2025'!$A$166:$A$190,0),MATCH($AC$2,'ERP2024'!$A$166:$E$166,0)))*100 -> 5.320378
A5: Andorra (Principality of) | B5: AND | C5: =IFERROR(INDEX('ERP2000'!$A$18:$F$159,MATCH(CRP!$A5,'ERP2000'!$A$18:$A$159,0),MATCH($AC$1,'ERP2000'!$A$20:$F$20,0))*100, "") | D5: =IFERROR(INDEX('ERP2001'!$A$18:$F$159,MATCH(CRP!$A5,'ERP2001'!$A$18:$A$159,0),MATCH($AC$1,'ERP2001'!$A$20:$F$20,0))*100, "") | E5: =IFERROR(INDEX('ERP2002'!$A$18:$F$159,MATCH(CRP!$A5,'ERP2002'!$A$18:$A$159,0),MATCH($AC$1,'ERP2002'!$A$21:$F$21,0))*100, "") | F5: =IFERROR(INDEX('ERP2003'!$A$18:$F$159,MATCH(CRP!$A5,'ERP2003'!$A$18:$A$159,0),MATCH($AC$1,'ERP2003'!$A$21:$F$21,0))*100, "") | G5: =IFERROR(INDEX('ERP2004'!$A$18:$F$159,MATCH(CRP!$A5,'ERP2004'!$A$18:$A$159,0),MATCH($AC$1,'ERP2004'!$A$21:$F$21,0))*100, "") | H5: =IFERROR(INDEX('ERP2005'!$A$18:$F$159,MATCH(CRP!$A5,'ERP2005'!$A$18:$A$159,0),MATCH($AC$1,'ERP2005'!$A$21:$F$21,0))*100, "") | I5: =IFERROR(INDEX('ERP2006'!$A$18:$F$159,MATCH(CRP!$A5,'ERP2006'!$A$18:$A$159,0),MATCH($AC$1,'ERP2006'!$A$21:$F$21,0))*100, "") | J5: =IFERROR(INDEX('ERP2007'!$A$18:$F$159,MATCH(CRP!$A5,'ERP2007'!$A$18:$A$159,0),MATCH($AC$1,'ERP2007'!$A$21:$F$21,0))*100, "") | K5: =IFERROR(INDEX('ERP2008'!$A$18:$F$159,MATCH(CRP!$A5,'ERP2008'!$A$18:$A$159,0),MATCH($AC$1,'ERP2008'!$A$21:$F$21,0))*100, "") | L5: =IFERROR(INDEX('ERP2009'!$A$18:$F$159,MATCH(CRP!$A5,'ERP2009'!$A$18:$A$159,0),MATCH($AC$1,'ERP2009'!$A$18:$F$18,0))*100, "") | M5: =IFERROR(INDEX('ERP2010'!$A$18:$F$159,MATCH(CRP!$A5,'ERP2010'!$A$18:$A$159,0),MATCH($AC$1,'ERP2010'!$A$18:$F$18,0))*100, "") | N5: =IFERROR(INDEX('ERP2011'!$A$18:$F$159,MATCH(CRP!$A5,'ERP2011'!$A$18:$A$159,0),MATCH($AC$1,'ERP2011'!$A$18:$F$18,0))*100, "") | O5: =IFERROR(IFERROR(INDEX('ERP2012'!$A$8:$F$159,MATCH(CRP!$A5,'ERP2012'!$A$8:$A$159,0),MATCH($AC$1,'ERP2012'!$A$7:$F$7,0)),INDEX('ERP2012'!$A$160:$E$184,MATCH(CRP!$A5,'ERP2012'!$A$160:$A$184,0),MATCH($AC$2,'ERP2012'!$A$160:$E$160,0)))*100, "") | P5: =IFERROR(IFERROR(INDEX('ERP2013'!$A$8:$F$159,MATCH(CRP!$A5,'ERP2013'!$A$8:$A$159,0),MATCH($AC$1,'ERP2013'!$A$7:$F$7,0)),INDEX('ERP2013'!$A$160:$E$184,MATCH(CRP!$A5,'ERP2013'!$A$160:$A$184,0),MATCH($AC$2,'ERP2013'!$A$160:$E$160,0)))*100, "") | Q5: =IFERROR(IFERROR(INDEX('ERP2014'!$A$8:$F$159,MATCH(CRP!$A5,'ERP2014'!$A$8:$A$159,0),MATCH($AC$1,'ERP2014'!$A$7:$F$7,0)),INDEX('ERP2014'!$A$160:$E$184,MATCH(CRP!$A5,'ERP2014'!$A$160:$A$184,0),MATCH($AC$2,'ERP2014'!$A$160:$E$160,0)))*100, "") -> 2.4 | R5: =IFERROR(IFERROR(INDEX('ERP2015'!$A$8:$F$159,MATCH(CRP!$A5,'ERP2015'!$A$8:$A$159,0),MATCH($AC$1,'ERP2015'!$A$7:$F$7,0)),INDEX('ERP2015'!$A$160:$E$184,MATCH(CRP!$A5,'ERP2015'!$A$160:$A$184,0),MATCH($AC$2,'ERP2015'!$A$160:$E$160,0)))*100, "") -> 3.458 | S5: =IFERROR(IFERROR(INDEX('ERP2016'!$A$8:$F$159,MATCH(CRP!$A5,'ERP2016'!$A$8:$A$159,0),MATCH($AC$1,'ERP2016'!$A$7:$F$7,0)),INDEX('ERP2016'!$A$160:$E$184,MATCH(CRP!$A5,'ERP2016'!$A$160:$A$184,0),MATCH($AC$2,'ERP2016'!$A$160:$E$160,0)))*100, "") -> 3.1290241 | T5: =IFERROR(IFERROR(INDEX('ERP2017'!$A$8:$F$159,MATCH(CRP!$A5,'ERP2017'!$A$8:$A$159,0),MATCH($AC$1,'ERP2017'!$A$7:$F$7,0)),INDEX('ERP2017'!$A$160:$E$190,MATCH(CRP!$A5,'ERP2017'!$A$160:$A$190,0),MATCH($AC$2,Table217[#Headers],0)))*100, "") -> 2.1944569 | U5: =IFERROR(IFERROR(INDEX('ERP2018'!$A$8:$F$159,MATCH(CRP!$A5,'ERP2018'!$A$8:$A$159,0),MATCH($AC$1,'ERP2018'!$A$7:$F$7,0)),INDEX('ERP2018'!$A$163:$E$190,MATCH(CRP!$A5,'ERP2018'!$A$163:$A$190,0),MATCH($AC$2,'ERP2018'!$A$163:$E$163,0)))*100, "") -> 2.6420491 | V5: =IFERROR(IFERROR(INDEX('ERP2019'!$A$8:$F$163,MATCH(CRP!$A5,'ERP2019'!$A$8:$A$163,0),MATCH($AC$1,'ERP2019'!$A$7:$F$7,0)),INDEX('ERP2019'!$A$165:$E$190,MATCH(CRP!$A5,'ERP2019'!$A$165:$A$190,0),MATCH($AC$2,'ERP2019'!$A$165:$E$165,0)))*100, "") -> 1.8773568 | W5: =IFERROR(INDEX('ERP2020'!$A$8:$F$165,MATCH(CRP!$A5,'ERP2020'!$A$8:$A$165,0),MATCH($AC$1,'ERP2020'!$A$7:$F$7,0)),INDEX('ERP2020'!$A$166:$E$190,MATCH(CRP!$A5,'ERP2020'!$A$166:$A$190,0),MATCH($AC$2,'ERP2020'!$A$166:$E$166,0)))*100 -> 7.260678 | X5: =IFERROR(INDEX('ERP2021'!$A$8:$F$165,MATCH(CRP!$A5,'ERP2021'!$A$8:$A$165,0),MATCH($AC$1,'ERP2021'!$A$7:$F$7,0)),INDEX('ERP2021'!$A$166:$E$190,MATCH(CRP!$A5,'ERP2021'!$A$166:$A$190,0),MATCH($AC$2,'ERP2021'!$A$166:$E$166,0)))*100 -> 1.8824657 | Y5: =IFERROR(INDEX('ERP2022'!$A$8:$F$165,MATCH(CRP!$A5,'ERP2022'!$A$8:$A$165,0),MATCH($AC$1,'ERP2022'!$A$7:$F$7,0)),INDEX('ERP2022'!$A$166:$E$190,MATCH(CRP!$A5,'ERP2022'!$A$166:$A$190,0),MATCH($AC$2,'ERP2022'!$A$166:$E$166,0)))*100 -> 3.2863024 | Z5: =IFERROR(INDEX('ERP2023'!$A$8:$F$165,MATCH(CRP!$A5,'ERP2023'!$A$8:$A$165,0),MATCH($AC$1,'ERP2023'!$A$7:$F$7,0)),INDEX('ERP2023'!$A$165:$E$190,MATCH(CRP!$A5,'ERP2023'!$A$165:$A$190,0),MATCH($AC$2,'ERP2023'!$A$165:$E$165,0)))*100 -> 2.7846543 | AA5: =IFERROR(INDEX('ERP2024'!$A$8:$F$165,MATCH(CRP!$A5,'ERP2024'!$A$8:$A$165,0),MATCH($AC$1,'ERP2024'!$A$7:$F$7,0)),INDEX('ERP2024'!$A$166:$E$190,MATCH(CRP!$A5,'ERP2024'!$A$166:$A$190,0),MATCH($AC$2,'ERP2024'!$A$166:$E$166,0)))*100 -> 2.1332209 | AB5: =IFERROR(INDEX('ERP2025'!$A$8:$F$165,MATCH(CRP!$A5,'ERP2025'!$A$8:$A$165,0),MATCH($AC$1,'ERP2025'!$A$7:$F$7,0)),INDEX('ERP2024'!$A$166:$E$190,MATCH(CRP!$A5,'ERP2025'!$A$166:$A$190,0),MATCH($AC$2,'ERP2024'!$A$166:$E$166,0)))*100 -> 2.3646125
A6: Angola | B6: AGO | C6: =IFERROR(INDEX('ERP2000'!$A$18:$F$159,MATCH(CRP!$A6,'ERP2000'!$A$18:$A$159,0),MATCH($AC$1,'ERP2000'!$A$20:$F$20,0))*100, "") | D6: =IFERROR(INDEX('ERP2001'!$A$18:$F$159,MATCH(CRP!$A6,'ERP2001'!$A$18:$A$159,0),MATCH($AC$1,'ERP2001'!$A$20:$F$20,0))*100, "") | E6: =IFERROR(INDEX('ERP2002'!$A$18:$F$159,MATCH(CRP!$A6,'ERP2002'!$A$18:$A$159,0),MATCH($AC$1,'ERP2002'!$A$21:$F$21,0))*100, "") | F6: =IFERROR(INDEX('ERP2003'!$A$18:$F$159,MATCH(CRP!$A6,'ERP2003'!$A$18:$A$159,0),MATCH($AC$1,'ERP2003'!$A$21:$F$21,0))*100, "") | G6: =IFERROR(INDEX('ERP2004'!$A$18:$F$159,MATCH(CRP!$A6,'ERP2004'!$A$18:$A$159,0),MATCH($AC$1,'ERP2004'!$A$21:$F$21,0))*100, "") | H6: =IFERROR(INDEX('ERP2005'!$A$18:$F$159,MATCH(CRP!$A6,'ERP2005'!$A$18:$A$159,0),MATCH($AC$1,'ERP2005'!$A$21:$F$21,0))*100, "") | I6: =IFERROR(INDEX('ERP2006'!$A$18:$F$159,MATCH(CRP!$A6,'ERP2006'!$A$18:$A$159,0),MATCH($AC$1,'ERP2006'!$A$21:$F$21,0))*100, "") | J6: =IFERROR(INDEX('ERP2007'!$A$18:$F$159,MATCH(CRP!$A6,'ERP2007'!$A$18:$A$159,0),MATCH($AC$1,'ERP2007'!$A$21:$F$21,0))*100, "") | K6: =IFERROR(INDEX('ERP2008'!$A$18:$F$159,MATCH(CRP!$A6,'ERP2008'!$A$18:$A$159,0),MATCH($AC$1,'ERP2008'!$A$21:$F$21,0))*100, "") | L6: =IFERROR(INDEX('ERP2009'!$A$18:$F$159,MATCH(CRP!$A6,'ERP2009'!$A$18:$A$159,0),MATCH($AC$1,'ERP2009'!$A$18:$F$18,0))*100, "") | M6: =IFERROR(INDEX('ERP2010'!$A$18:$F$159,MATCH(CRP!$A6,'ERP2010'!$A$18:$A$159,0),MATCH($AC$1,'ERP2010'!$A$18:$F$18,0))*100, "") -> 6 | N6: =IFERROR(INDEX('ERP2011'!$A$18:$F$159,MATCH(CRP!$A6,'ERP2011'!$A$18:$A$159,0),MATCH($AC$1,'ERP2011'!$A$18:$F$18,0))*100, "") -> 4.875 | O6: =IFERROR(IFERROR(INDEX('ERP2012'!$A$8:$F$159,MATCH(CRP!$A6,'ERP2012'!$A$8:$A$159,0),MATCH($AC$1,'ERP2012'!$A$7:$F$7,0)),INDEX('ERP2012'!$A$160:$E$184,MATCH(CRP!$A6,'ERP2012'!$A$160:$A$184,0),MATCH($AC$2,'ERP2012'!$A$160:$E$160,0)))*100, "") -> 4.875 | P6: =IFERROR(IFERROR(INDEX('ERP2013'!$A$8:$F$159,MATCH(CRP!$A6,'ERP2013'!$A$8:$A$159,0),MATCH($AC$1,'ERP2013'!$A$7:$F$7,0)),INDEX('ERP2013'!$A$160:$E$184,MATCH(CRP!$A6,'ERP2013'!$A$160:$A$184,0),MATCH($AC$2,'ERP2013'!$A$160:$E$160,0)))*100, "") -> 5.4 | Q6: =IFERROR(IFERROR(INDEX('ERP2014'!$A$8:$F$159,MATCH(CRP!$A6,'ERP2014'!$A$8:$A$159,0),MATCH($AC$1,'ERP2014'!$A$7:$F$7,0)),INDEX('ERP2014'!$A$160:$E$184,MATCH(CRP!$A6,'ERP2014'!$A$160:$A$184,0),MATCH($AC$2,'ERP2014'!$A$160:$E$160,0)))*100, "") -> 4.5 | R6: =IFERROR(IFERROR(INDEX('ERP2015'!$A$8:$F$159,MATCH(CRP!$A6,'ERP2015'!$A$8:$A$159,0),MATCH($AC$1,'ERP2015'!$A$7:$F$7,0)),INDEX('ERP2015'!$A$160:$E$184,MATCH(CRP!$A6,'ERP2015'!$A$160:$A$184,0),MATCH($AC$2,'ERP2015'!$A$160:$E$160,0)))*100, "") -> 7.07 | S6: =IFERROR(IFERROR(INDEX('ERP2016'!$A$8:$F$159,MATCH(CRP!$A6,'ERP2016'!$A$8:$A$159,0),MATCH($AC$1,'ERP2016'!$A$7:$F$7,0)),INDEX('ERP2016'!$A$160:$E$184,MATCH(CRP!$A6,'ERP2016'!$A$160:$A$184,0),MATCH($AC$2,'ERP2016'!$A$160:$E$160,0)))*100, "") -> 6.3991107 | T6: =IFERROR(IFERROR(INDEX('ERP2017'!$A$8:$F$159,MATCH(CRP!$A6,'ERP2017'!$A$8:$A$159,0),MATCH($AC$1,'ERP2017'!$A$7:$F$7,0)),INDEX('ERP2017'!$A$160:$E$190,MATCH(CRP!$A6,'ERP2017'!$A$160:$A$190,0),MATCH($AC$2,Table217[#Headers],0)))*100, "") -> 6.3441644 | U6: =IFERROR(IFERROR(INDEX('ERP2018'!$A$8:$F$159,MATCH(CRP!$A6,'ERP2018'!$A$8:$A$159,0),MATCH($AC$1,'ERP2018'!$A$7:$F$7,0)),INDEX('ERP2018'!$A$163:$E$190,MATCH(CRP!$A6,'ERP2018'!$A$163:$A$190,0),MATCH($AC$2,'ERP2018'!$A$163:$E$163,0)))*100, "") -> 9.0280447 | V6: =IFERROR(IFERROR(INDEX('ERP2019'!$A$8:$F$163,MATCH(CRP!$A6,'ERP2019'!$A$8:$A$163,0),MATCH($AC$1,'ERP2019'!$A$7:$F$7,0)),INDEX('ERP2019'!$A$165:$E$190,MATCH(CRP!$A6,'ERP2019'!$A$165:$A$190,0),MATCH($AC$2,'ERP2019'!$A$165:$E$165,0)))*100, "") -> 6.4150439 | W6: =IFERROR(INDEX('ERP2020'!$A$8:$F$165,MATCH(CRP!$A6,'ERP2020'!$A$8:$A$165,0),MATCH($AC$1,'ERP2020'!$A$7:$F$7,0)),INDEX('ERP2020'!$A$166:$E$190,MATCH(CRP!$A6,'ERP2020'!$A$166:$A$190,0),MATCH($AC$2,'ERP2020'!$A$166:$E$166,0)))*100 -> 7.260678 | X6: =IFERROR(INDEX('ERP2021'!$A$8:$F$165,MATCH(CRP!$A6,'ERP2021'!$A$8:$A$165,0),MATCH($AC$1,'ERP2021'!$A$7:$F$7,0)),INDEX('ERP2021'!$A$166:$E$190,MATCH(CRP!$A6,'ERP2021'!$A$166:$A$190,0),MATCH($AC$2,'ERP2021'!$A$166:$E$166,0)))*100 -> 6.4325014 | Y6: =IFERROR(INDEX('ERP2022'!$A$8:$F$165,MATCH(CRP!$A6,'ERP2022'!$A$8:$A$165,0),MATCH($AC$1,'ERP2022'!$A$7:$F$7,0)),INDEX('ERP2022'!$A$166:$E$190,MATCH(CRP!$A6,'ERP2022'!$A$166:$A$190,0),MATCH($AC$2,'ERP2022'!$A$166:$E$166,0)))*100 -> 11.218057 | Z6: =IFERROR(INDEX('ERP2023'!$A$8:$F$165,MATCH(CRP!$A6,'ERP2023'!$A$8:$A$165,0),MATCH($AC$1,'ERP2023'!$A$7:$F$7,0)),INDEX('ERP2023'!$A$165:$E$190,MATCH(CRP!$A6,'ERP2023'!$A$165:$A$190,0),MATCH($AC$2,'ERP2023'!$A$165:$E$165,0)))*100 -> 9.5056408 | AA6: =IFERROR(INDEX('ERP2024'!$A$8:$F$165,MATCH(CRP!$A6,'ERP2024'!$A$8:$A$165,0),MATCH($AC$1,'ERP2024'!$A$7:$F$7,0)),INDEX('ERP2024'!$A$166:$E$190,MATCH(CRP!$A6,'ERP2024'!$A$166:$A$190,0),MATCH($AC$2,'ERP2024'!$A$166:$E$166,0)))*100 -> 8.6740525 | AB6: =IFERROR(INDEX('ERP2025'!$A$8:$F$165,MATCH(CRP!$A6,'ERP2025'!$A$8:$A$165,0),MATCH($AC$1,'ERP2025'!$A$7:$F$7,0)),INDEX('ERP2024'!$A$166:$E$190,MATCH(CRP!$A6,'ERP2025'!$A$166:$A$190,0),MATCH($AC$2,'ERP2024'!$A$166:$E$166,0)))*100 -> 9.6149315
A7: Argentina | B7: ARG | C7: =IFERROR(INDEX('ERP2000'!$A$18:$F$159,MATCH(CRP!$A7,'ERP2000'!$A$18:$A$159,0),MATCH($AC$1,'ERP2000'!$A$20:$F$20,0))*100, "") -> 11.25 | D7: =IFERROR(INDEX('ERP2001'!$A$18:$F$159,MATCH(CRP!$A7,'ERP2001'!$A$18:$A$159,0),MATCH($AC$1,'ERP2001'!$A$20:$F$20,0))*100, "") -> 13.5 | E7: =IFERROR(INDEX('ERP2002'!$A$18:$F$159,MATCH(CRP!$A7,'ERP2002'!$A$18:$A$159,0),MATCH($AC$1,'ERP2002'!$A$21:$F$21,0))*100, "") -> 13.5 | F7: =IFERROR(INDEX('ERP2003'!$A$18:$F$159,MATCH(CRP!$A7,'ERP2003'!$A$18:$A$159,0),MATCH($AC$1,'ERP2003'!$A$21:$F$21,0))*100, "") -> 12.75 | G7: =IFERROR(INDEX('ERP2004'!$A$18:$F$159,MATCH(CRP!$A7,'ERP2004'!$A$18:$A$159,0),MATCH($AC$1,'ERP2004'!$A$21:$F$21,0))*100, "") -> 12.75 | H7: =IFERROR(INDEX('ERP2005'!$A$18:$F$159,MATCH(CRP!$A7,'ERP2005'!$A$18:$A$159,0),MATCH($AC$1,'ERP2005'!$A$21:$F$21,0))*100, "") -> 9 | I7: =IFERROR(INDEX('ERP2006'!$A$18:$F$159,MATCH(CRP!$A7,'ERP2006'!$A$18:$A$159,0),MATCH($AC$1,'ERP2006'!$A$21:$F$21,0))*100, "") -> 6.75 | J7: =IFERROR(INDEX('ERP2007'!$A$18:$F$159,MATCH(CRP!$A7,'ERP2007'!$A$18:$A$159,0),MATCH($AC$1,'ERP2007'!$A$21:$F$21,0))*100, "") -> 6.75 | K7: =IFERROR(INDEX('ERP2008'!$A$18:$F$159,MATCH(CRP!$A7,'ERP2008'!$A$18:$A$159,0),MATCH($AC$1,'ERP2008'!$A$21:$F$21,0))*100, "") -> 13.5 | L7: =IFERROR(INDEX('ERP2009'!$A$18:$F$159,MATCH(CRP!$A7,'ERP2009'!$A$18:$A$159,0),MATCH($AC$1,'ERP2009'!$A$18:$F$18,0))*100, "") -> 9.75 | M7: =IFERROR(INDEX('ERP2010'!$A$18:$F$159,MATCH(CRP!$A7,'ERP2010'!$A$18:$A$159,0),MATCH($AC$1,'ERP2010'!$A$18:$F$18,0))*100, "") -> 9 | N7: =IFERROR(INDEX('ERP2011'!$A$18:$F$159,MATCH(CRP!$A7,'ERP2011'!$A$18:$A$159,0),MATCH($AC$1,'ERP2011'!$A$18:$F$18,0))*100, "") -> 9 | O7: =IFERROR(IFERROR(INDEX('ERP2012'!$A$8:$F$159,MATCH(CRP!$A7,'ERP2012'!$A$8:$A$159,0),MATCH($AC$1,'ERP2012'!$A$7:$F$7,0)),INDEX('ERP2012'!$A$160:$E$184,MATCH(CRP!$A7,'ERP2012'!$A$160:$A$184,0),MATCH($AC$2,'ERP2012'!$A$160:$E$160,0)))*100, "") -> 9 | P7: =IFERROR(IFERROR(INDEX('ERP2013'!$A$8:$F$159,MATCH(CRP!$A7,'ERP2013'!$A$8:$A$159,0),MATCH($AC$1,'ERP2013'!$A$7:$F$7,0)),INDEX('ERP2013'!$A$160:$E$184,MATCH(CRP!$A7,'ERP2013'!$A$160:$A$184,0),MATCH($AC$2,'ERP2013'!$A$160:$E$160,0)))*100, "") -> 9.75 | Q7: =IFERROR(IFERROR(INDEX('ERP2014'!$A$8:$F$159,MATCH(CRP!$A7,'ERP2014'!$A$8:$A$159,0),MATCH($AC$1,'ERP2014'!$A$7:$F$7,0)),INDEX('ERP2014'!$A$160:$E$184,MATCH(CRP!$A7,'ERP2014'!$A$160:$A$184,0),MATCH($AC$2,'ERP2014'!$A$160:$E$160,0)))*100, "") -> 11.25 | R7: =IFERROR(IFERROR(INDEX('ERP2015'!$A$8:$F$159,MATCH(CRP!$A7,'ERP2015'!$A$8:$A$159,0),MATCH($AC$1,'ERP2015'!$A$7:$F$7,0)),INDEX('ERP2015'!$A$160:$E$184,MATCH(CRP!$A7,'ERP2015'!$A$160:$A$184,0),MATCH($AC$2,'ERP2015'!$A$160:$E$160,0)))*100, "") -> 10.206 | S7: =IFERROR(IFERROR(INDEX('ERP2016'!$A$8:$F$159,MATCH(CRP!$A7,'ERP2016'!$A$8:$A$159,0),MATCH($AC$1,'ERP2016'!$A$7:$F$7,0)),INDEX('ERP2016'!$A$160:$E$184,MATCH(CRP!$A7,'ERP2016'!$A$160:$A$184,0),MATCH($AC$2,'ERP2016'!$A$160:$E$160,0)))*100, "") -> 9.2460096 | T7: =IFERROR(IFERROR(INDEX('ERP2017'!$A$8:$F$159,MATCH(CRP!$A7,'ERP2017'!$A$8:$A$159,0),MATCH($AC$1,'ERP2017'!$A$7:$F$7,0)),INDEX('ERP2017'!$A$160:$E$190,MATCH(CRP!$A7,'ERP2017'!$A$160:$A$190,0),MATCH($AC$2,Table217[#Headers],0)))*100, "") -> 6.3441644 | U7: =IFERROR(IFERROR(INDEX('ERP2018'!$A$8:$F$159,MATCH(CRP!$A7,'ERP2018'!$A$8:$A$159,0),MATCH($AC$1,'ERP2018'!$A$7:$F$7,0)),INDEX('ERP2018'!$A$163:$E$190,MATCH(CRP!$A7,'ERP2018'!$A$163:$A$190,0),MATCH($AC$2,'ERP2018'!$A$163:$E$163,0)))*100, "") -> 7.6381516 | V7: =IFERROR(IFERROR(INDEX('ERP2019'!$A$8:$F$163,MATCH(CRP!$A7,'ERP2019'!$A$8:$A$163,0),MATCH($AC$1,'ERP2019'!$A$7:$F$7,0)),INDEX('ERP2019'!$A$165:$E$190,MATCH(CRP!$A7,'ERP2019'!$A$165:$A$190,0),MATCH($AC$2,'ERP2019'!$A$165:$E$165,0)))*100, "") -> 8.8796309 | W7: =IFERROR(INDEX('ERP2020'!$A$8:$F$165,MATCH(CRP!$A7,'ERP2020'!$A$8:$A$165,0),MATCH($AC$1,'ERP2020'!$A$7:$F$7,0)),INDEX('ERP2020'!$A$166:$E$190,MATCH(CRP!$A7,'ERP2020'!$A$166:$A$190,0),MATCH($AC$2,'ERP2020'!$A$166:$E$166,0)))*100 -> 11.62058 | X7: =IFERROR(INDEX('ERP2021'!$A$8:$F$165,MATCH(CRP!$A7,'ERP2021'!$A$8:$A$165,0),MATCH($AC$1,'ERP2021'!$A$7:$F$7,0)),INDEX('ERP2021'!$A$166:$E$190,MATCH(CRP!$A7,'ERP2021'!$A$166:$A$190,0),MATCH($AC$2,'ERP2021'!$A$166:$E$166,0)))*100 -> 11.865779 | Y7: =IFERROR(INDEX('ERP2022'!$A$8:$F$165,MATCH(CRP!$A7,'ERP2022'!$A$8:$A$165,0),MATCH($AC$1,'ERP2022'!$A$7:$F$7,0)),INDEX('ERP2022'!$A$166:$E$190,MATCH(CRP!$A7,'ERP2022'!$A$166:$A$190,0),MATCH($AC$2,'ERP2022'!$A$166:$E$166,0)))*100 -> 20.711819 | Z7: =IFERROR(INDEX('ERP2023'!$A$8:$F$165,MATCH(CRP!$A7,'ERP2023'!$A$8:$A$165,0),MATCH($AC$1,'ERP2023'!$A$7:$F$7,0)),INDEX('ERP2023'!$A$165:$E$190,MATCH(CRP!$A7,'ERP2023'!$A$165:$A$190,0),MATCH($AC$2,'ERP2023'!$A$165:$E$165,0)))*100 -> 17.550198 | AA7: =IFERROR(INDEX('ERP2024'!$A$8:$F$165,MATCH(CRP!$A7,'ERP2024'!$A$8:$A$165,0),MATCH($AC$1,'ERP2024'!$A$7:$F$7,0)),INDEX('ERP2024'!$A$166:$E$190,MATCH(CRP!$A7,'ERP2024'!$A$166:$A$190,0),MATCH($AC$2,'ERP2024'!$A$166:$E$166,0)))*100 -> 16.014842 | AB7: =IFERROR(INDEX('ERP2025'!$A$8:$F$165,MATCH(CRP!$A7,'ERP2025'!$A$8:$A$165,0),MATCH($AC$1,'ERP2025'!$A$7:$F$7,0)),INDEX('ERP2024'!$A$166:$E$190,MATCH(CRP!$A7,'ERP2025'!$A$166:$A$190,0),MATCH($AC$2,'ERP2024'!$A$166:$E$166,0)))*100 -> 14.796215
A8: Armenia | B8: ARM | C8: =IFERROR(INDEX('ERP2000'!$A$18:$F$159,MATCH(CRP!$A8,'ERP2000'!$A$18:$A$159,0),MATCH($AC$1,'ERP2000'!$A$20:$F$20,0))*100, "") | D8: =IFERROR(INDEX('ERP2001'!$A$18:$F$159,MATCH(CRP!$A8,'ERP2001'!$A$18:$A$159,0),MATCH($AC$1,'ERP2001'!$A$20:$F$20,0))*100, "") | E8: =IFERROR(INDEX('ERP2002'!$A$18:$F$159,MATCH(CRP!$A8,'ERP2002'!$A$18:$A$159,0),MATCH($AC$1,'ERP2002'!$A$21:$F$21,0))*100, "") | F8: =IFERROR(INDEX('ERP2003'!$A$18:$F$159,MATCH(CRP!$A8,'ERP2003'!$A$18:$A$159,0),MATCH($AC$1,'ERP2003'!$A$21:$F$21,0))*100, "") | G8: =IFERROR(INDEX('ERP2004'!$A$18:$F$159,MATCH(CRP!$A8,'ERP2004'!$A$18:$A$159,0),MATCH($AC$1,'ERP2004'!$A$21:$F$21,0))*100, "") | H8: =IFERROR(INDEX('ERP2005'!$A$18:$F$159,MATCH(CRP!$A8,'ERP2005'!$A$18:$A$159,0),MATCH($AC$1,'ERP2005'!$A$21:$F$21,0))*100, "") | I8: =IFERROR(INDEX('ERP2006'!$A$18:$F$159,MATCH(CRP!$A8,'ERP2006'!$A$18:$A$159,0),MATCH($AC$1,'ERP2006'!$A$21:$F$21,0))*100, "") -> 3.75 | J8: =IFERROR(INDEX('ERP2007'!$A$18:$F$159,MATCH(CRP!$A8,'ERP2007'!$A$18:$A$159,0),MATCH($AC$1,'ERP2007'!$A$21:$F$21,0))*100, "") -> 3.75 | K8: =IFERROR(INDEX('ERP2008'!$A$18:$F$159,MATCH(CRP!$A8,'ERP2008'!$A$18:$A$159,0),MATCH($AC$1,'ERP2008'!$A$21:$F$21,0))*100, "") -> 6 | L8: =IFERROR(INDEX('ERP2009'!$A$18:$F$159,MATCH(CRP!$A8,'ERP2009'!$A$18:$A$159,0),MATCH($AC$1,'ERP2009'!$A$18:$F$18,0))*100, "") -> 4.5 | M8: =IFERROR(INDEX('ERP2010'!$A$18:$F$159,MATCH(CRP!$A8,'ERP2010'!$A$18:$A$159,0),MATCH($AC$1,'ERP2010'!$A$18:$F$18,0))*100, "") -> 4.125 | N8: =IFERROR(INDEX('ERP2011'!$A$18:$F$159,MATCH(CRP!$A8,'ERP2011'!$A$18:$A$159,0),MATCH($AC$1,'ERP2011'!$A$18:$F$18,0))*100, "") -> 4.125 | O8: =IFERROR(IFERROR(INDEX('ERP2012'!$A$8:$F$159,MATCH(CRP!$A8,'ERP2012'!$A$8:$A$159,0),MATCH($AC$1,'ERP2012'!$A$7:$F$7,0)),INDEX('ERP2012'!$A$160:$E$184,MATCH(CRP!$A8,'ERP2012'!$A$160:$A$184,0),MATCH($AC$2,'ERP2012'!$A$160:$E$160,0)))*100, "") -> 4.125 | P8: =IFERROR(IFERROR(INDEX('ERP2013'!$A$8:$F$159,MATCH(CRP!$A8,'ERP2013'!$A$8:$A$159,0),MATCH($AC$1,'ERP2013'!$A$7:$F$7,0)),INDEX('ERP2013'!$A$160:$E$184,MATCH(CRP!$A8,'ERP2013'!$A$160:$A$184,0),MATCH($AC$2,'ERP2013'!$A$160:$E$160,0)))*100, "") -> 4.5 | Q8: =IFERROR(IFERROR(INDEX('ERP2014'!$A$8:$F$159,MATCH(CRP!$A8,'ERP2014'!$A$8:$A$159,0),MATCH($AC$1,'ERP2014'!$A$7:$F$7,0)),INDEX('ERP2014'!$A$160:$E$184,MATCH(CRP!$A8,'ERP2014'!$A$160:$A$184,0),MATCH($AC$2,'ERP2014'!$A$160:$E$160,0)))*100, "") -> 4.5 | R8: =IFERROR(IFERROR(INDEX('ERP2015'!$A$8:$F$159,MATCH(CRP!$A8,'ERP2015'!$A$8:$A$159,0),MATCH($AC$1,'ERP2015'!$A$7:$F$7,0)),INDEX('ERP2015'!$A$160:$E$184,MATCH(CRP!$A8,'ERP2015'!$A$160:$A$184,0),MATCH($AC$2,'ERP2015'!$A$160:$E$160,0)))*100, "") -> 7.07 | S8: =IFERROR(IFERROR(INDEX('ERP2016'!$A$8:$F$159,MATCH(CRP!$A8,'ERP2016'!$A$8:$A$159,0),MATCH($AC$1,'ERP2016'!$A$7:$F$7,0)),INDEX('ERP2016'!$A$160:$E$184,MATCH(CRP!$A8,'ERP2016'!$A$160:$A$184,0),MATCH($AC$2,'ERP2016'!$A$160:$E$160,0)))*100, "") -> 6.3991107 | T8: =IFERROR(IFERROR(INDEX('ERP2017'!$A$8:$F$159,MATCH(CRP!$A8,'ERP2017'!$A$8:$A$159,0),MATCH($AC$1,'ERP2017'!$A$7:$F$7,0)),INDEX('ERP2017'!$A$160:$E$190,MATCH(CRP!$A8,'ERP2017'!$A$160:$A$190,0),MATCH($AC$2,Table217[#Headers],0)))*100, "") -> 5.1897345 | U8: =IFERROR(IFERROR(INDEX('ERP2018'!$A$8:$F$159,MATCH(CRP!$A8,'ERP2018'!$A$8:$A$159,0),MATCH($AC$1,'ERP2018'!$A$7:$F$7,0)),INDEX('ERP2018'!$A$163:$E$190,MATCH(CRP!$A8,'ERP2018'!$A$163:$A$190,0),MATCH($AC$2,'ERP2018'!$A$163:$E$163,0)))*100, "") -> 6.2482584 | V8: =IFERROR(IFERROR(INDEX('ERP2019'!$A$8:$F$163,MATCH(CRP!$A8,'ERP2019'!$A$8:$A$163,0),MATCH($AC$1,'ERP2019'!$A$7:$F$7,0)),INDEX('ERP2019'!$A$165:$E$190,MATCH(CRP!$A8,'ERP2019'!$A$165:$A$190,0),MATCH($AC$2,'ERP2019'!$A$165:$E$165,0)))*100, "") -> 3.5500729 | W8: =IFERROR(INDEX('ERP2020'!$A$8:$F$165,MATCH(CRP!$A8,'ERP2020'!$A$8:$A$165,0),MATCH($AC$1,'ERP2020'!$A$7:$F$7,0)),INDEX('ERP2020'!$A$166:$E$190,MATCH(CRP!$A8,'ERP2020'!$A$166:$A$190,0),MATCH($AC$2,'ERP2020'!$A$166:$E$166,0)))*100 -> 3.4861739 | X8: =IFERROR(INDEX('ERP2021'!$A$8:$F$165,MATCH(CRP!$A8,'ERP2021'!$A$8:$A$165,0),MATCH($AC$1,'ERP2021'!$A$7:$F$7,0)),INDEX('ERP2021'!$A$166:$E$190,MATCH(CRP!$A8,'ERP2021'!$A$166:$A$190,0),MATCH($AC$2,'ERP2021'!$A$166:$E$166,0)))*100 -> 3.5597338 | Y8: =IFERROR(INDEX('ERP2022'!$A$8:$F$165,MATCH(CRP!$A8,'ERP2022'!$A$8:$A$165,0),MATCH($AC$1,'ERP2022'!$A$7:$F$7,0)),INDEX('ERP2022'!$A$166:$E$190,MATCH(CRP!$A8,'ERP2022'!$A$166:$A$190,0),MATCH($AC$2,'ERP2022'!$A$166:$E$166,0)))*100 -> 6.20746 | Z8: =IFERROR(INDEX('ERP2023'!$A$8:$F$165,MATCH(CRP!$A8,'ERP2023'!$A$8:$A$165,0),MATCH($AC$1,'ERP2023'!$A$7:$F$7,0)),INDEX('ERP2023'!$A$165:$E$190,MATCH(CRP!$A8,'ERP2023'!$A$165:$A$190,0),MATCH($AC$2,'ERP2023'!$A$165:$E$165,0)))*100 -> 5.2599025 | AA8: =IFERROR(INDEX('ERP2024'!$A$8:$F$165,MATCH(CRP!$A8,'ERP2024'!$A$8:$A$165,0),MATCH($AC$1,'ERP2024'!$A$7:$F$7,0)),INDEX('ERP2024'!$A$166:$E$190,MATCH(CRP!$A8,'ERP2024'!$A$166:$A$190,0),MATCH($AC$2,'ERP2024'!$A$166:$E$166,0)))*100 -> 4.7997469 | AB8: =IFERROR(INDEX('ERP2025'!$A$8:$F$165,MATCH(CRP!$A8,'ERP2025'!$A$8:$A$165,0),MATCH($AC$1,'ERP2025'!$A$7:$F$7,0)),INDEX('ERP2024'!$A$166:$E$190,MATCH(CRP!$A8,'ERP2025'!$A$166:$A$190,0),MATCH($AC$2,'ERP2024'!$A$166:$E$166,0)))*100 -> 5.320378
A9: Aruba | B9: ABW | C9: =IFERROR(INDEX('ERP2000'!$A$18:$F$159,MATCH(CRP!$A9,'ERP2000'!$A$18:$A$159,0),MATCH($AC$1,'ERP2000'!$A$20:$F$20,0))*100, "") | D9: =IFERROR(INDEX('ERP2001'!$A$18:$F$159,MATCH(CRP!$A9,'ERP2001'!$A$18:$A$159,0),MATCH($AC$1,'ERP2001'!$A$20:$F$20,0))*100, "") | E9: =IFERROR(INDEX('ERP2002'!$A$18:$F$159,MATCH(CRP!$A9,'ERP2002'!$A$18:$A$159,0),MATCH($AC$1,'ERP2002'!$A$21:$F$21,0))*100, "") | F9: =IFERROR(INDEX('ERP2003'!$A$18:$F$159,MATCH(CRP!$A9,'ERP2003'!$A$18:$A$159,0),MATCH($AC$1,'ERP2003'!$A$21:$F$21,0))*100, "") | G9: =IFERROR(INDEX('ERP2004'!$A$18:$F$159,MATCH(CRP!$A9,'ERP2004'!$A$18:$A$159,0),MATCH($AC$1,'ERP2004'!$A$21:$F$21,0))*100, "") | H9: =IFERROR(INDEX('ERP2005'!$A$18:$F$159,MATCH(CRP!$A9,'ERP2005'!$A$18:$A$159,0),MATCH($AC$1,'ERP2005'!$A$21:$F$21,0))*100, "") | I9: =IFERROR(INDEX('ERP2006'!$A$18:$F$159,MATCH(CRP!$A9,'ERP2006'!$A$18:$A$159,0),MATCH($AC$1,'ERP2006'!$A$21:$F$21,0))*100, "") | J9: =IFERROR(INDEX('ERP2007'!$A$18:$F$159,MATCH(CRP!$A9,'ERP2007'!$A$18:$A$159,0),MATCH($AC$1,'ERP2007'!$A$21:$F$21,0))*100, "") | K9: =IFERROR(INDEX('ERP2008'!$A$18:$F$159,MATCH(CRP!$A9,'ERP2008'!$A$18:$A$159,0),MATCH($AC$1,'ERP2008'!$A$21:$F$21,0))*100, "") | L9: =IFERROR(INDEX('ERP2009'!$A$18:$F$159,MATCH(CRP!$A9,'ERP2009'!$A$18:$A$159,0),MATCH($AC$1,'ERP2009'!$A$18:$F$18,0))*100, "") | M9: =IFERROR(INDEX('ERP2010'!$A$18:$F$159,MATCH(CRP!$A9,'ERP2010'!$A$18:$A$159,0),MATCH($AC$1,'ERP2010'!$A$18:$F$18,0))*100, "") | N9: =IFERROR(INDEX('ERP2011'!$A$18:$F$159,MATCH(CRP!$A9,'ERP2011'!$A$18:$A$159,0),MATCH($AC$1,'ERP2011'!$A$18:$F$18,0))*100, "") | O9: =IFERROR(IFERROR(INDEX('ERP2012'!$A$8:$F$159,MATCH(CRP!$A9,'ERP2012'!$A$8:$A$159,0),MATCH($AC$1,'ERP2012'!$A$7:$F$7,0)),INDEX('ERP2012'!$A$160:$E$184,MATCH(CRP!$A9,'ERP2012'!$A$160:$A$184,0),MATCH($AC$2,'ERP2012'!$A$160:$E$160,0)))*100, "") | P9: =IFERROR(IFERROR(INDEX('ERP2013'!$A$8:$F$159,MATCH(CRP!$A9,'ERP2013'!$A$8:$A$159,0),MATCH($AC$1,'ERP2013'!$A$7:$F$7,0)),INDEX('ERP2013'!$A$160:$E$184,MATCH(CRP!$A9,'ERP2013'!$A$160:$A$184,0),MATCH($AC$2,'ERP2013'!$A$160:$E$160,0)))*100, "") -> 2.4 | Q9: =IFERROR(IFERROR(INDEX('ERP2014'!$A$8:$F$159,MATCH(CRP!$A9,'ERP2014'!$A$8:$A$159,0),MATCH($AC$1,'ERP2014'!$A$7:$F$7,0)),INDEX('ERP2014'!$A$160:$E$184,MATCH(CRP!$A9,'ERP2014'!$A$160:$A$184,0),MATCH($AC$2,'ERP2014'!$A$160:$E$160,0)))*100, "") -> 2.4 | R9: =IFERROR(IFERROR(INDEX('ERP2015'!$A$8:$F$159,MATCH(CRP!$A9,'ERP2015'!$A$8:$A$159,0),MATCH($AC$1,'ERP2015'!$A$7:$F$7,0)),INDEX('ERP2015'!$A$160:$E$184,MATCH(CRP!$A9,'ERP2015'!$A$160:$A$184,0),MATCH($AC$2,'ERP2015'!$A$160:$E$160,0)))*100, "") -> 2.506 | S9: =IFERROR(IFERROR(INDEX('ERP2016'!$A$8:$F$159,MATCH(CRP!$A9,'ERP2016'!$A$8:$A$159,0),MATCH($AC$1,'ERP2016'!$A$7:$F$7,0)),INDEX('ERP2016'!$A$160:$E$184,MATCH(CRP!$A9,'ERP2016'!$A$160:$A$184,0),MATCH($AC$2,'ERP2016'!$A$160:$E$160,0)))*100, "") -> 2.2698248 | T9: =IFERROR(IFERROR(INDEX('ERP2017'!$A$8:$F$159,MATCH(CRP!$A9,'ERP2017'!$A$8:$A$159,0),MATCH($AC$1,'ERP2017'!$A$7:$F$7,0)),INDEX('ERP2017'!$A$160:$E$190,MATCH(CRP!$A9,'ERP2017'!$A$160:$A$190,0),MATCH($AC$2,Table217[#Headers],0)))*100, "") -> 1.8408477 | U9: =IFERROR(IFERROR(INDEX('ERP2018'!$A$8:$F$159,MATCH(CRP!$A9,'ERP2018'!$A$8:$A$159,0),MATCH($AC$1,'ERP2018'!$A$7:$F$7,0)),INDEX('ERP2018'!$A$163:$E$190,MATCH(CRP!$A9,'ERP2018'!$A$163:$A$190,0),MATCH($AC$2,'ERP2018'!$A$163:$E$163,0)))*100, "") -> 2.2163161 | V9: =IFERROR(IFERROR(INDEX('ERP2019'!$A$8:$F$163,MATCH(CRP!$A9,'ERP2019'!$A$8:$A$163,0),MATCH($AC$1,'ERP2019'!$A$7:$F$7,0)),INDEX('ERP2019'!$A$165:$E$190,MATCH(CRP!$A9,'ERP2019'!$A$165:$A$190,0),MATCH($AC$2,'ERP2019'!$A$165:$E$165,0)))*100, "") -> 1.5748444 | W9: =IFERROR(INDEX('ERP2020'!$A$8:$F$165,MATCH(CRP!$A9,'ERP2020'!$A$8:$A$165,0),MATCH($AC$1,'ERP2020'!$A$7:$F$7,0)),INDEX('ERP2020'!$A$166:$E$190,MATCH(CRP!$A9,'ERP2020'!$A$166:$A$190,0),MATCH($AC$2,'ERP2020'!$A$166:$E$166,0)))*100 -> 1.5464982 | X9: =IFERROR(INDEX('ERP2021'!$A$8:$F$165,MATCH(CRP!$A9,'ERP2021'!$A$8:$A$165,0),MATCH($AC$1,'ERP2021'!$A$7:$F$7,0)),INDEX('ERP2021'!$A$166:$E$190,MATCH(CRP!$A9,'ERP2021'!$A$166:$A$190,0),MATCH($AC$2,'ERP2021'!$A$166:$E$166,0)))*100 -> 1.8824657 | Y9: =IFERROR(INDEX('ERP2022'!$A$8:$F$165,MATCH(CRP!$A9,'ERP2022'!$A$8:$A$165,0),MATCH($AC$1,'ERP2022'!$A$7:$F$7,0)),INDEX('ERP2022'!$A$166:$E$190,MATCH(CRP!$A9,'ERP2022'!$A$166:$A$190,0),MATCH($AC$2,'ERP2022'!$A$166:$E$166,0)))*100 -> 3.2863024 | Z9: =IFERROR(INDEX('ERP2023'!$A$8:$F$165,MATCH(CRP!$A9,'ERP2023'!$A$8:$A$165,0),MATCH($AC$1,'ERP2023'!$A$7:$F$7,0)),INDEX('ERP2023'!$A$165:$E$190,MATCH(CRP!$A9,'ERP2023'!$A$165:$A$190,0),MATCH($AC$2,'ERP2023'!$A$165:$E$165,0)))*100 -> 2.7846543 | AA9: =IFERROR(INDEX('ERP2024'!$A$8:$F$165,MATCH(CRP!$A9,'ERP2024'!$A$8:$A$165,0),MATCH($AC$1,'ERP2024'!$A$7:$F$7,0)),INDEX('ERP2024'!$A$166:$E$190,MATCH(CRP!$A9,'ERP2024'!$A$166:$A$190,0),MATCH($AC$2,'ERP2024'!$A$166:$E$166,0)))*100 -> 2.9331787 | AB9: =IFERROR(INDEX('ERP2025'!$A$8:$F$165,MATCH(CRP!$A9,'ERP2025'!$A$8:$A$165,0),MATCH($AC$1,'ERP2025'!$A$7:$F$7,0)),INDEX('ERP2024'!$A$166:$E$190,MATCH(CRP!$A9,'ERP2025'!$A$166:$A$190,0),MATCH($AC$2,'ERP2024'!$A$166:$E$166,0)))*100 -> 3.2513421
A10: Australia | B10: AUS | C10: =IFERROR(INDEX('ERP2000'!$A$18:$F$159,MATCH(CRP!$A10,'ERP2000'!$A$18:$A$159,0),MATCH($AC$1,'ERP2000'!$A$20:$F$20,0))*100, "") -> 1.275 | D10: =IFERROR(INDEX('ERP2001'!$A$18:$F$159,MATCH(CRP!$A10,'ERP2001'!$A$18:$A$159,0),MATCH($AC$1,'ERP2001'!$A$20:$F$20,0))*100, "") -> 1.275 | E10: =IFERROR(INDEX('ERP2002'!$A$18:$F$159,MATCH(CRP!$A10,'ERP2002'!$A$18:$A$159,0),MATCH($AC$1,'ERP2002'!$A$21:$F$21,0))*100, "") -> 0 | F10: =IFERROR(INDEX('ERP2003'!$A$18:$F$159,MATCH(CRP!$A10,'ERP2003'!$A$18:$A$159,0),MATCH($AC$1,'ERP2003'!$A$21:$F$21,0))*100, "") -> 0 | G10: =IFERROR(INDEX('ERP2004'!$A$18:$F$159,MATCH(CRP!$A10,'ERP2004'!$A$18:$A$159,0),MATCH($AC$1,'ERP2004'!$A$21:$F$21,0))*100, "") -> 0 | H10: =IFERROR(INDEX('ERP2005'!$A$18:$F$159,MATCH(CRP!$A10,'ERP2005'!$A$18:$A$159,0),MATCH($AC$1,'ERP2005'!$A$21:$F$21,0))*100, "") -> 0 | I10: =IFERROR(INDEX('ERP2006'!$A$18:$F$159,MATCH(CRP!$A10,'ERP2006'!$A$18:$A$159,0),MATCH($AC$1,'ERP2006'!$A$21:$F$21,0))*100, "") -> 0 | J10: =IFERROR(INDEX('ERP2007'!$A$18:$F$159,MATCH(CRP!$A10,'ERP2007'!$A$18:$A$159,0),MATCH($AC$1,'ERP2007'!$A$21:$F$21,0))*100, "") -> 0 | K10: =IFERROR(INDEX('ERP2008'!$A$18:$F$159,MATCH(CRP!$A10,'ERP2008'!$A$18:$A$159,0),MATCH($AC$1,'ERP2008'!$A$21:$F$21,0))*100, "") -> 0 | L10: =IFERROR(INDEX('ERP2009'!$A$18:$F$159,MATCH(CRP!$A10,'ERP2009'!$A$18:$A$159,0),MATCH($AC$1,'ERP2009'!$A$18:$F$18,0))*100, "") -> 0 | M10: =IFERROR(INDEX('ERP2010'!$A$18:$F$159,MATCH(CRP!$A10,'ERP2010'!$A$18:$A$159,0),MATCH($AC$1,'ERP2010'!$A$18:$F$18,0))*100, "") -> 0 | N10: =IFERROR(INDEX('ERP2011'!$A$18:$F$159,MATCH(CRP!$A10,'ERP2011'!$A$18:$A$159,0),MATCH($AC$1,'ERP2011'!$A$18:$F$18,0))*100, "") -> 0 | O10: =IFERROR(IFERROR(INDEX('ERP2012'!$A$8:$F$159,MATCH(CRP!$A10,'ERP2012'!$A$8:$A$159,0),MATCH($AC$1,'ERP2012'!$A$7:$F$7,0)),INDEX('ERP2012'!$A$160:$E$184,MATCH(CRP!$A10,'ERP2012'!$A$160:$A$184,0),MATCH($AC$2,'ERP2012'!$A$160:$E$160,0)))*100, "") -> 0 | P10: =IFERROR(IFERROR(INDEX('ERP2013'!$A$8:$F$159,MATCH(CRP!$A10,'ERP2013'!$A$8:$A$159,0),MATCH($AC$1,'ERP2013'!$A$7:$F$7,0)),INDEX('ERP2013'!$A$160:$E$184,MATCH(CRP!$A10,'ERP2013'!$A$160:$A$184,0),MATCH($AC$2,'ERP2013'!$A$160:$E$160,0)))*100, "") -> 0 | Q10: =IFERROR(IFERROR(INDEX('ERP2014'!$A$8:$F$159,MATCH(CRP!$A10,'ERP2014'!$A$8:$A$159,0),MATCH($AC$1,'ERP2014'!$A$7:$F$7,0)),INDEX('ERP2014'!$A$160:$E$184,MATCH(CRP!$A10,'ERP2014'!$A$160:$A$184,0),MATCH($AC$2,'ERP2014'!$A$160:$E$160,0)))*100, "") -> 0 | R10: =IFERROR(IFERROR(INDEX('ERP2015'!$A$8:$F$159,MATCH(CRP!$A10,'ERP2015'!$A$8:$A$159,0),MATCH($AC$1,'ERP2015'!$A$7:$F$7,0)),INDEX('ERP2015'!$A$160:$E$184,MATCH(CRP!$A10,'ERP2015'!$A$160:$A$184,0),MATCH($AC$2,'ERP2015'!$A$160:$E$160,0)))*100, "") -> 0 | S10: =IFERROR(IFERROR(INDEX('ERP2016'!$A$8:$F$159,MATCH(CRP!$A10,'ERP2016'!$A$8:$A$159,0),MATCH($AC$1,'ERP2016'!$A$7:$F$7,0)),INDEX('ERP2016'!$A$160:$E$184,MATCH(CRP!$A10,'ERP2016'!$A$160:$A$184,0),MATCH($AC$2,'ERP2016'!$A$160:$E$160,0)))*100, "") -> 0 | T10: =IFERROR(IFERROR(INDEX('ERP2017'!$A$8:$F$159,MATCH(CRP!$A10,'ERP2017'!$A$8:$A$159,0),MATCH($AC$1,'ERP2017'!$A$7:$F$7,0)),INDEX('ERP2017'!$A$160:$E$190,MATCH(CRP!$A10,'ERP2017'!$A$160:$A$190,0),MATCH($AC$2,Table217[#Headers],0)))*100, "") -> 0 | U10: =IFERROR(IFERROR(INDEX('ERP2018'!$A$8:$F$159,MATCH(CRP!$A10,'ERP2018'!$A$8:$A$159,0),MATCH($AC$1,'ERP2018'!$A$7:$F$7,0)),INDEX('ERP2018'!$A$163:$E$190,MATCH(CRP!$A10,'ERP2018'!$A$163:$A$190,0),MATCH($AC$2,'ERP2018'!$A$163:$E$163,0)))*100, "") -> 0 | V10: =IFERROR(IFERROR(INDEX('ERP2019'!$A$8:$F$163,MATCH(CRP!$A10,'ERP2019'!$A$8:$A$163,0),MATCH($AC$1,'ERP2019'!$A$7:$F$7,0)),INDEX('ERP2019'!$A$165:$E$190,MATCH(CRP!$A10,'ERP2019'!$A$165:$A$190,0),MATCH($AC$2,'ERP2019'!$A$165:$E$165,0)))*100, "") -> 0 | W10: =IFERROR(INDEX('ERP2020'!$A$8:$F$165,MATCH(CRP!$A10,'ERP2020'!$A$8:$A$165,0),MATCH($AC$1,'ERP2020'!$A$7:$F$7,0)),INDEX('ERP2020'!$A$166:$E$190,MATCH(CRP!$A10,'ERP2020'!$A$166:$A$190,0),MATCH($AC$2,'ERP2020'!$A$166:$E$166,0)))*100 -> 0 | X10: =IFERROR(INDEX('ERP2021'!$A$8:$F$165,MATCH(CRP!$A10,'ERP2021'!$A$8:$A$165,0),MATCH($AC$1,'ERP2021'!$A$7:$F$7,0)),INDEX('ERP2021'!$A$166:$E$190,MATCH(CRP!$A10,'ERP2021'!$A$166:$A$190,0),MATCH($AC$2,'ERP2021'!$A$166:$E$166,0)))*100 -> 0 | Y10: =IFERROR(INDEX('ERP2022'!$A$8:$F$165,MATCH(CRP!$A10,'ERP2022'!$A$8:$A$165,0),MATCH($AC$1,'ERP2022'!$A$7:$F$7,0)),INDEX('ERP2022'!$A$166:$E$190,MATCH(CRP!$A10,'ERP2022'!$A$166:$A$190,0),MATCH($AC$2,'ERP2022'!$A$166:$E$166,0)))*100 -> 0 | Z10: =IFERROR(INDEX('ERP2023'!$A$8:$F$165,MATCH(CRP!$A10,'ERP2023'!$A$8:$A$165,0),MATCH($AC$1,'ERP2023'!$A$7:$F$7,0)),INDEX('ERP2023'!$A$165:$E$190,MATCH(CRP!$A10,'ERP2023'!$A$165:$A$190,0),MATCH($AC$2,'ERP2023'!$A$165:$E$165,0)))*100 -> 0 | AA10: =IFERROR(INDEX('ERP2024'!$A$8:$F$165,MATCH(CRP!$A10,'ERP2024'!$A$8:$A$165,0),MATCH($AC$1,'ERP2024'!$A$7:$F$7,0)),INDEX('ERP2024'!$A$166:$E$190,MATCH(CRP!$A10,'ERP2024'!$A$166:$A$190,0),MATCH($AC$2,'ERP2024'!$A$166:$E$166,0)))*100 -> 0 | AB10: =IFERROR(INDEX('ERP2025'!$A$8:$F$165,MATCH(CRP!$A10,'ERP2025'!$A$8:$A$165,0),MATCH($AC$1,'ERP2025'!$A$7:$F$7,0)),INDEX('ERP2024'!$A$166:$E$190,MATCH(CRP!$A10,'ERP2025'!$A$166:$A$190,0),MATCH($AC$2,'ERP2024'!$A$166:$E$166,0)))*100 -> 0
A11: Austria | B11: AUT | C11: =IFERROR(INDEX('ERP2000'!$A$18:$F$159,MATCH(CRP!$A11,'ERP2000'!$A$18:$A$159,0),MATCH($AC$1,'ERP2000'!$A$20:$F$20,0))*100, "") -> 0 | D11: =IFERROR(INDEX('ERP2001'!$A$18:$F$159,MATCH(CRP!$A11,'ERP2001'!$A$18:$A$159,0),MATCH($AC$1,'ERP2001'!$A$20:$F$20,0))*100, "") -> 0 | E11: =IFERROR(INDEX('ERP2002'!$A$18:$F$159,MATCH(CRP!$A11,'ERP2002'!$A$18:$A$159,0),MATCH($AC$1,'ERP2002'!$A$21:$F$21,0))*100, "") -> 0 | F11: =IFERROR(INDEX('ERP2003'!$A$18:$F$159,MATCH(CRP!$A11,'ERP2003'!$A$18:$A$159,0),MATCH($AC$1,'ERP2003'!$A$21:$F$21,0))*100, "") -> 0 | G11: =IFERROR(INDEX('ERP2004'!$A$18:$F$159,MATCH(CRP!$A11,'ERP2004'!$A$18:$A$159,0),MATCH($AC$1,'ERP2004'!$A$21:$F$21,0))*100, "") -> 0 | H11: =IFERROR(INDEX('ERP2005'!$A$18:$F$159,MATCH(CRP!$A11,'ERP2005'!$A$18:$A$159,0),MATCH($AC$1,'ERP2005'!$A$21:$F$21,0))*100, "") -> 0 | I11: =IFERROR(INDEX('ERP2006'!$A$18:$F$159,MATCH(CRP!$A11,'ERP2006'!$A$18:$A$159,0),MATCH($AC$1,'ERP2006'!$A$21:$F$21,0))*100, "") -> 0 | J11: =IFERROR(INDEX('ERP2007'!$A$18:$F$159,MATCH(CRP!$A11,'ERP2007'!$A$18:$A$159,0),MATCH($AC$1,'ERP2007'!$A$21:$F$21,0))*100, "") -> 0 | K11: =IFERROR(INDEX('ERP2008'!$A$18:$F$159,MATCH(CRP!$A11,'ERP2008'!$A$18:$A$159,0),MATCH($AC$1,'ERP2008'!$A$21:$F$21,0))*100, "") -> 0 | L11: =IFERROR(INDEX('ERP2009'!$A$18:$F$159,MATCH(CRP!$A11,'ERP2009'!$A$18:$A$159,0),MATCH($AC$1,'ERP2009'!$A$18:$F$18,0))*100, "") | M11: =IFERROR(INDEX('ERP2010'!$A$18:$F$159,MATCH(CRP!$A11,'ERP2010'!$A$18:$A$159,0),MATCH($AC$1,'ERP2010'!$A$18:$F$18,0))*100, "") -> 0 | N11: =IFERROR(INDEX('ERP2011'!$A$18:$F$159,MATCH(CRP!$A11,'ERP2011'!$A$18:$A$159,0),MATCH($AC$1,'ERP2011'!$A$18:$F$18,0))*100, "") | O11: =IFERROR(IFERROR(INDEX('ERP2012'!$A$8:$F$159,MATCH(CRP!$A11,'ERP2012'!$A$8:$A$159,0),MATCH($AC$1,'ERP2012'!$A$7:$F$7,0)),INDEX('ERP2012'!$A$160:$E$184,MATCH(CRP!$A11,'ERP2012'!$A$160:$A$184,0),MATCH($AC$2,'ERP2012'!$A$160:$E$160,0)))*100, "") -> 0 | P11: =IFERROR(IFERROR(INDEX('ERP2013'!$A$8:$F$159,MATCH(CRP!$A11,'ERP2013'!$A$8:$A$159,0),MATCH($AC$1,'ERP2013'!$A$7:$F$7,0)),INDEX('ERP2013'!$A$160:$E$184,MATCH(CRP!$A11,'ERP2013'!$A$160:$A$184,0),MATCH($AC$2,'ERP2013'!$A$160:$E$160,0)))*100, "") -> 0 | Q11: =IFERROR(IFERROR(INDEX('ERP2014'!$A$8:$F$159,MATCH(CRP!$A11,'ERP2014'!$A$8:$A$159,0),MATCH($AC$1,'ERP2014'!$A$7:$F$7,0)),INDEX('ERP2014'!$A$160:$E$184,MATCH(CRP!$A11,'ERP2014'!$A$160:$A$184,0),MATCH($AC$2,'ERP2014'!$A$160:$E$160,0)))*100, "") -> 0 | R11: =IFERROR(IFERROR(INDEX('ERP2015'!$A$8:$F$159,MATCH(CRP!$A11,'ERP2015'!$A$8:$A$159,0),MATCH($AC$1,'ERP2015'!$A$7:$F$7,0)),INDEX('ERP2015'!$A$160:$E$184,MATCH(CRP!$A11,'ERP2015'!$A$160:$A$184,0),MATCH($AC$2,'ERP2015'!$A$160:$E$160,0)))*100, "") -> 0.63 | S11: =IFERROR(IFERROR(INDEX('ERP2016'!$A$8:$F$159,MATCH(CRP!$A11,'ERP2016'!$A$8:$A$159,0),MATCH($AC$1,'ERP2016'!$A$7:$F$7,0)),INDEX('ERP2016'!$A$160:$E$184,MATCH(CRP!$A11,'ERP2016'!$A$160:$A$184,0),MATCH($AC$2,'ERP2016'!$A$160:$E$160,0)))*100, "") -> 0.56425024 | T11: =IFERROR(IFERROR(INDEX('ERP2017'!$A$8:$F$159,MATCH(CRP!$A11,'ERP2017'!$A$8:$A$159,0),MATCH($AC$1,'ERP2017'!$A$7:$F$7,0)),INDEX('ERP2017'!$A$160:$E$190,MATCH(CRP!$A11,'ERP2017'!$A$160:$A$190,0),MATCH($AC$2,Table217[#Headers],0)))*100, "") -> 0.45761186 | U11: =IFERROR(IFERROR(INDEX('ERP2018'!$A$8:$F$159,MATCH(CRP!$A11,'ERP2018'!$A$8:$A$159,0),MATCH($AC$1,'ERP2018'!$A$7:$F$7,0)),INDEX('ERP2018'!$A$163:$E$190,MATCH(CRP!$A11,'ERP2018'!$A$163:$A$190,0),MATCH($AC$2,'ERP2018'!$A$163:$E$163,0)))*100, "") -> 0.55094864 | V11: =IFERROR(IFERROR(INDEX('ERP2019'!$A$8:$F$163,MATCH(CRP!$A11,'ERP2019'!$A$8:$A$163,0),MATCH($AC$1,'ERP2019'!$A$7:$F$7,0)),INDEX('ERP2019'!$A$165:$E$190,MATCH(CRP!$A11,'ERP2019'!$A$165:$A$190,0),MATCH($AC$2,'ERP2019'!$A$165:$E$165,0)))*100, "") -> 0.39148673 | W11: =IFERROR(INDEX('ERP2020'!$A$8:$F$165,MATCH(CRP!$A11,'ERP2020'!$A$8:$A$165,0),MATCH($AC$1,'ERP2020'!$A$7:$F$7,0)),INDEX('ERP2020'!$A$166:$E$190,MATCH(CRP!$A11,'ERP2020'!$A$166:$A$190,0),MATCH($AC$2,'ERP2020'!$A$166:$E$166,0)))*100 -> 0.38444023 | X11: =IFERROR(INDEX('ERP2021'!$A$8:$F$165,MATCH(CRP!$A11,'ERP2021'!$A$8:$A$165,0),MATCH($AC$1,'ERP2021'!$A$7:$F$7,0)),INDEX('ERP2021'!$A$166:$E$190,MATCH(CRP!$A11,'ERP2021'!$A$166:$A$190,0),MATCH($AC$2,'ERP2021'!$A$166:$E$166,0)))*100 -> 0.3925521 | Y11: =IFERROR(INDEX('ERP2022'!$A$8:$F$165,MATCH(CRP!$A11,'ERP2022'!$A$8:$A$165,0),MATCH($AC$1,'ERP2022'!$A$7:$F$7,0)),INDEX('ERP2022'!$A$166:$E$190,MATCH(CRP!$A11,'ERP2022'!$A$166:$A$190,0),MATCH($AC$2,'ERP2022'!$A$166:$E$166,0)))*100 -> 0.68971778 | Z11: =IFERROR(INDEX('ERP2023'!$A$8:$F$165,MATCH(CRP!$A11,'ERP2023'!$A$8:$A$165,0),MATCH($AC$1,'ERP2023'!$A$7:$F$7,0)),INDEX('ERP2023'!$A$165:$E$190,MATCH(CRP!$A11,'ERP2023'!$A$165:$A$190,0),MATCH($AC$2,'ERP2023'!$A$165:$E$165,0)))*100 -> 0.58443361 | AA11: =IFERROR(INDEX('ERP2024'!$A$8:$F$165,MATCH(CRP!$A11,'ERP2024'!$A$8:$A$165,0),MATCH($AC$1,'ERP2024'!$A$7:$F$7,0)),INDEX('ERP2024'!$A$166:$E$190,MATCH(CRP!$A11,'ERP2024'!$A$166:$A$190,0),MATCH($AC$2,'ERP2024'!$A$166:$E$166,0)))*100 -> 0.53330522 | AB11: =IFERROR(INDEX('ERP2025'!$A$8:$F$165,MATCH(CRP!$A11,'ERP2025'!$A$8:$A$165,0),MATCH($AC$1,'ERP2025'!$A$7:$F$7,0)),INDEX('ERP2024'!$A$166:$E$190,MATCH(CRP!$A11,'ERP2025'!$A$166:$A$190,0),MATCH($AC$2,'ERP2024'!$A$166:$E$166,0)))*100 -> 0.40623236
A12: Azerbaijan | B12: AZE | C12: =IFERROR(INDEX('ERP2000'!$A$18:$F$159,MATCH(CRP!$A12,'ERP2000'!$A$18:$A$159,0),MATCH($AC$1,'ERP2000'!$A$20:$F$20,0))*100, "") | D12: =IFERROR(INDEX('ERP2001'!$A$18:$F$159,MATCH(CRP!$A12,'ERP2001'!$A$18:$A$159,0),MATCH($AC$1,'ERP2001'!$A$20:$F$20,0))*100, "") | E12: =IFERROR(INDEX('ERP2002'!$A$18:$F$159,MATCH(CRP!$A12,'ERP2002'!$A$18:$A$159,0),MATCH($AC$1,'ERP2002'!$A$21:$F$21,0))*100, "") | F12: =IFERROR(INDEX('ERP2003'!$A$18:$F$159,MATCH(CRP!$A12,'ERP2003'!$A$18:$A$159,0),MATCH($AC$1,'ERP2003'!$A$21:$F$21,0))*100, "") | G12: =IFERROR(INDEX('ERP2004'!$A$18:$F$159,MATCH(CRP!$A12,'ERP2004'!$A$18:$A$159,0),MATCH($AC$1,'ERP2004'!$A$21:$F$21,0))*100, "") | H12: =IFERROR(INDEX('ERP2005'!$A$18:$F$159,MATCH(CRP!$A12,'ERP2005'!$A$18:$A$159,0),MATCH($AC$1,'ERP2005'!$A$21:$F$21,0))*100, "") | I12: =IFERROR(INDEX('ERP2006'!$A$18:$F$159,MATCH(CRP!$A12,'ERP2006'!$A$18:$A$159,0),MATCH($AC$1,'ERP2006'!$A$21:$F$21,0))*100, "") -> 3 | J12: =IFERROR(INDEX('ERP2007'!$A$18:$F$159,MATCH(CRP!$A12,'ERP2007'!$A$18:$A$159,0),MATCH($AC$1,'ERP2007'!$A$21:$F$21,0))*100, "") -> 3 | K12: =IFERROR(INDEX('ERP2008'!$A$18:$F$159,MATCH(CRP!$A12,'ERP2008'!$A$18:$A$159,0),MATCH($AC$1,'ERP2008'!$A$21:$F$21,0))*100, "") -> 4.5 | L12: =IFERROR(INDEX('ERP2009'!$A$18:$F$159,MATCH(CRP!$A12,'ERP2009'!$A$18:$A$159,0),MATCH($AC$1,'ERP2009'!$A$18:$F$18,0))*100, "") -> 3.75 | M12: =IFERROR(INDEX('ERP2010'!$A$18:$F$159,MATCH(CRP!$A12,'ERP2010'!$A$18:$A$159,0),MATCH($AC$1,'ERP2010'!$A$18:$F$18,0))*100, "") -> 3.6 | N12: =IFERROR(INDEX('ERP2011'!$A$18:$F$159,MATCH(CRP!$A12,'ERP2011'!$A$18:$A$159,0),MATCH($AC$1,'ERP2011'!$A$18:$F$18,0))*100, "") -> 3.6 | O12: =IFERROR(IFERROR(INDEX('ERP2012'!$A$8:$F$159,MATCH(CRP!$A12,'ERP2012'!$A$8:$A$159,0),MATCH($AC$1,'ERP2012'!$A$7:$F$7,0)),INDEX('ERP2012'!$A$160:$E$184,MATCH(CRP!$A12,'ERP2012'!$A$160:$A$184,0),MATCH($AC$2,'ERP2012'!$A$160:$E$160,0)))*100, "") -> 3 | P12: =IFERROR(IFERROR(INDEX('ERP2013'!$A$8:$F$159,MATCH(CRP!$A12,'ERP2013'!$A$8:$A$159,0),MATCH($AC$1,'ERP2013'!$A$7:$F$7,0)),INDEX('ERP2013'!$A$160:$E$184,MATCH(CRP!$A12,'ERP2013'!$A$160:$A$184,0),MATCH($AC$2,'ERP2013'!$A$160:$E$160,0)))*100, "") -> 3.3 | Q12: =IFERROR(IFERROR(INDEX('ERP2014'!$A$8:$F$159,MATCH(CRP!$A12,'ERP2014'!$A$8:$A$159,0),MATCH($AC$1,'ERP2014'!$A$7:$F$7,0)),INDEX('ERP2014'!$A$160:$E$184,MATCH(CRP!$A12,'ERP2014'!$A$160:$A$184,0),MATCH($AC$2,'ERP2014'!$A$160:$E$160,0)))*100, "") -> 3.3 | R12: =IFERROR(IFERROR(INDEX('ERP2015'!$A$8:$F$159,MATCH(CRP!$A12,'ERP2015'!$A$8:$A$159,0),MATCH($AC$1,'ERP2015'!$A$7:$F$7,0)),INDEX('ERP2015'!$A$160:$E$184,MATCH(CRP!$A12,'ERP2015'!$A$160:$A$184,0),MATCH($AC$2,'ERP2015'!$A$160:$E$160,0)))*100, "") -> 3.92 | S12: =IFERROR(IFERROR(INDEX('ERP2016'!$A$8:$F$159,MATCH(CRP!$A12,'ERP2016'!$A$8:$A$159,0),MATCH($AC$1,'ERP2016'!$A$7:$F$7,0)),INDEX('ERP2016'!$A$160:$E$184,MATCH(CRP!$A12,'ERP2016'!$A$160:$A$184,0),MATCH($AC$2,'ERP2016'!$A$160:$E$160,0)))*100, "") -> 3.5522117 | T12: =IFERROR(IFERROR(INDEX('ERP2017'!$A$8:$F$159,MATCH(CRP!$A12,'ERP2017'!$A$8:$A$159,0),MATCH($AC$1,'ERP2017'!$A$7:$F$7,0)),INDEX('ERP2017'!$A$160:$E$190,MATCH(CRP!$A12,'ERP2017'!$A$160:$A$190,0),MATCH($AC$2,Table217[#Headers],0)))*100, "") -> 3.4632897 | U12: =IFERROR(IFERROR(INDEX('ERP2018'!$A$8:$F$159,MATCH(CRP!$A12,'ERP2018'!$A$8:$A$159,0),MATCH($AC$1,'ERP2018'!$A$7:$F$7,0)),INDEX('ERP2018'!$A$163:$E$190,MATCH(CRP!$A12,'ERP2018'!$A$163:$A$190,0),MATCH($AC$2,'ERP2018'!$A$163:$E$163,0)))*100, "") -> 4.1696795 | V12: =IFERROR(IFERROR(INDEX('ERP2019'!$A$8:$F$163,MATCH(CRP!$A12,'ERP2019'!$A$8:$A$163,0),MATCH($AC$1,'ERP2019'!$A$7:$F$7,0)),INDEX('ERP2019'!$A$165:$E$190,MATCH(CRP!$A12,'ERP2019'!$A$165:$A$190,0),MATCH($AC$2,'ERP2019'!$A$165:$E$165,0)))*100, "") -> 2.9628428 | W12: =IFERROR(INDEX('ERP2020'!$A$8:$F$165,MATCH(CRP!$A12,'ERP2020'!$A$8:$A$165,0),MATCH($AC$1,'ERP2020'!$A$7:$F$7,0)),INDEX('ERP2020'!$A$166:$E$190,MATCH(CRP!$A12,'ERP2020'!$A$166:$A$190,0),MATCH($AC$2,'ERP2020'!$A$166:$E$166,0)))*100 -> 2.9095136 | X12: =IFERROR(INDEX('ERP2021'!$A$8:$F$165,MATCH(CRP!$A12,'ERP2021'!$A$8:$A$165,0),MATCH($AC$1,'ERP2021'!$A$7:$F$7,0)),INDEX('ERP2021'!$A$166:$E$190,MATCH(CRP!$A12,'ERP2021'!$A$166:$A$190,0),MATCH($AC$2,'ERP2021'!$A$166:$E$166,0)))*100 -> 2.9709057 | Y12: =IFERROR(INDEX('ERP2022'!$A$8:$F$165,MATCH(CRP!$A12,'ERP2022'!$A$8:$A$165,0),MATCH($AC$1,'ERP2022'!$A$7:$F$7,0)),INDEX('ERP2022'!$A$166:$E$190,MATCH(CRP!$A12,'ERP2022'!$A$166:$A$190,0),MATCH($AC$2,'ERP2022'!$A$166:$E$166,0)))*100 -> 4.320879 | Z12: =IFERROR(INDEX('ERP2023'!$A$8:$F$165,MATCH(CRP!$A12,'ERP2023'!$A$8:$A$165,0),MATCH($AC$1,'ERP2023'!$A$7:$F$7,0)),INDEX('ERP2023'!$A$165:$E$190,MATCH(CRP!$A12,'ERP2023'!$A$165:$A$190,0),MATCH($AC$2,'ERP2023'!$A$165:$E$165,0)))*100 -> 3.6613047 | AA12: =IFERROR(INDEX('ERP2024'!$A$8:$F$165,MATCH(CRP!$A12,'ERP2024'!$A$8:$A$165,0),MATCH($AC$1,'ERP2024'!$A$7:$F$7,0)),INDEX('ERP2024'!$A$166:$E$190,MATCH(CRP!$A12,'ERP2024'!$A$166:$A$190,0),MATCH($AC$2,'ERP2024'!$A$166:$E$166,0)))*100 -> 3.3410003 | AB12: =IFERROR(INDEX('ERP2025'!$A$8:$F$165,MATCH(CRP!$A12,'ERP2025'!$A$8:$A$165,0),MATCH($AC$1,'ERP2025'!$A$7:$F$7,0)),INDEX('ERP2024'!$A$166:$E$190,MATCH(CRP!$A12,'ERP2025'!$A$166:$A$190,0),MATCH($AC$2,'ERP2024'!$A$166:$E$166,0)))*100 -> 3.2513421
A13: Bahamas | B13: BHS | C13: =IFERROR(INDEX('ERP2000'!$A$18:$F$159,MATCH(CRP!$A13,'ERP2000'!$A$18:$A$159,0),MATCH($AC$1,'ERP2000'!$A$20:$F$20,0))*100, "") -> 2.025 | D13: =IFERROR(INDEX('ERP2001'!$A$18:$F$159,MATCH(CRP!$A13,'ERP2001'!$A$18:$A$159,0),MATCH($AC$1,'ERP2001'!$A$20:$F$20,0))*100, "") -> 2.025 | E13: =IFERROR(INDEX('ERP2002'!$A$18:$F$159,MATCH(CRP!$A13,'ERP2002'!$A$18:$A$159,0),MATCH($AC$1,'ERP2002'!$A$21:$F$21,0))*100, "") -> 1.5 | F13: =IFERROR(INDEX('ERP2003'!$A$18:$F$159,MATCH(CRP!$A13,'ERP2003'!$A$18:$A$159,0),MATCH($AC$1,'ERP2003'!$A$21:$F$21,0))*100, "") -> 1.5 | G13: =IFERROR(INDEX('ERP2004'!$A$18:$F$159,MATCH(CRP!$A13,'ERP2004'!$A$18:$A$159,0),MATCH($AC$1,'ERP2004'!$A$21:$F$21,0))*100, "") -> 1.5 | H13: =IFERROR(INDEX('ERP2005'!$A$18:$F$159,MATCH(CRP!$A13,'ERP2005'!$A$18:$A$159,0),MATCH($AC$1,'ERP2005'!$A$21:$F$21,0))*100, "") -> 0.9 | I13: =IFERROR(INDEX('ERP2006'!$A$18:$F$159,MATCH(CRP!$A13,'ERP2006'!$A$18:$A$159,0),MATCH($AC$1,'ERP2006'!$A$21:$F$21,0))*100, "") -> 1.05 | J13: =IFERROR(INDEX('ERP2007'!$A$18:$F$159,MATCH(CRP!$A13,'ERP2007'!$A$18:$A$159,0),MATCH($AC$1,'ERP2007'!$A$21:$F$21,0))*100, "") -> 1.05 | K13: =IFERROR(INDEX('ERP2008'!$A$18:$F$159,MATCH(CRP!$A13,'ERP2008'!$A$18:$A$159,0),MATCH($AC$1,'ERP2008'!$A$21:$F$21,0))*100, "") -> 2.1 | L13: =IFERROR(INDEX('ERP2009'!$A$18:$F$159,MATCH(CRP!$A13,'ERP2009'!$A$18:$A$159,0),MATCH($AC$1,'ERP2009'!$A$18:$F$18,0))*100, "") -> 1.8 | M13: =IFERROR(INDEX('ERP2010'!$A$18:$F$159,MATCH(CRP!$A13,'ERP2010'!$A$18:$A$159,0),MATCH($AC$1,'ERP2010'!$A$18:$F$18,0))*100, "") -> 1.725 | N13: =IFERROR(INDEX('ERP2011'!$A$18:$F$159,MATCH(CRP!$A13,'ERP2011'!$A$18:$A$159,0),MATCH($AC$1,'ERP2011'!$A$18:$F$18,0))*100, "") -> 1.725 | O13: =IFERROR(IFERROR(INDEX('ERP2012'!$A$8:$F$159,MATCH(CRP!$A13,'ERP2012'!$A$8:$A$159,0),MATCH($AC$1,'ERP2012'!$A$7:$F$7,0)),INDEX('ERP2012'!$A$160:$E$184,MATCH(CRP!$A13,'ERP2012'!$A$160:$A$184,0),MATCH($AC$2,'ERP2012'!$A$160:$E$160,0)))*100, "") -> 2.25 | P13: =IFERROR(IFERROR(INDEX('ERP2013'!$A$8:$F$159,MATCH(CRP!$A13,'ERP2013'!$A$8:$A$159,0),MATCH($AC$1,'ERP2013'!$A$7:$F$7,0)),INDEX('ERP2013'!$A$160:$E$184,MATCH(CRP!$A13,'ERP2013'!$A$160:$A$184,0),MATCH($AC$2,'ERP2013'!$A$160:$E$160,0)))*100, "") -> 2.4 | Q13: =IFERROR(IFERROR(INDEX('ERP2014'!$A$8:$F$159,MATCH(CRP!$A13,'ERP2014'!$A$8:$A$159,0),MATCH($AC$1,'ERP2014'!$A$7:$F$7,0)),INDEX('ERP2014'!$A$160:$E$184,MATCH(CRP!$A13,'ERP2014'!$A$160:$A$184,0),MATCH($AC$2,'ERP2014'!$A$160:$E$160,0)))*100, "") -> 2.85 | R13: =IFERROR(IFERROR(INDEX('ERP2015'!$A$8:$F$159,MATCH(CRP!$A13,'ERP2015'!$A$8:$A$159,0),MATCH($AC$1,'ERP2015'!$A$7:$F$7,0)),INDEX('ERP2015'!$A$160:$E$184,MATCH(CRP!$A13,'ERP2015'!$A$160:$A$184,0),MATCH($AC$2,'ERP2015'!$A$160:$E$160,0)))*100, "") -> 2.982 | S13: =IFERROR(IFERROR(INDEX('ERP2016'!$A$8:$F$159,MATCH(CRP!$A13,'ERP2016'!$A$8:$A$159,0),MATCH($AC$1,'ERP2016'!$A$7:$F$7,0)),INDEX('ERP2016'!$A$160:$E$184,MATCH(CRP!$A13,'ERP2016'!$A$160:$A$184,0),MATCH($AC$2,'ERP2016'!$A$160:$E$160,0)))*100, "") -> 3.1290241 | T13: =IFERROR(IFERROR(INDEX('ERP2017'!$A$8:$F$159,MATCH(CRP!$A13,'ERP2017'!$A$8:$A$159,0),MATCH($AC$1,'ERP2017'!$A$7:$F$7,0)),INDEX('ERP2017'!$A$160:$E$190,MATCH(CRP!$A13,'ERP2017'!$A$160:$A$190,0),MATCH($AC$2,Table217[#Headers],0)))*100, "") -> 2.5376657 | U13: =IFERROR(IFERROR(INDEX('ERP2018'!$A$8:$F$159,MATCH(CRP!$A13,'ERP2018'!$A$8:$A$159,0),MATCH($AC$1,'ERP2018'!$A$7:$F$7,0)),INDEX('ERP2018'!$A$163:$E$190,MATCH(CRP!$A13,'ERP2018'!$A$163:$A$190,0),MATCH($AC$2,'ERP2018'!$A$163:$E$163,0)))*100, "") -> 3.0552606 | V13: =IFERROR(IFERROR(INDEX('ERP2019'!$A$8:$F$163,MATCH(CRP!$A13,'ERP2019'!$A$8:$A$163,0),MATCH($AC$1,'ERP2019'!$A$7:$F$7,0)),INDEX('ERP2019'!$A$165:$E$190,MATCH(CRP!$A13,'ERP2019'!$A$165:$A$190,0),MATCH($AC$2,'ERP2019'!$A$165:$E$165,0)))*100, "") -> 2.1709719 | W13: =IFERROR(INDEX('ERP2020'!$A$8:$F$165,MATCH(CRP!$A13,'ERP2020'!$A$8:$A$165,0),MATCH($AC$1,'ERP2020'!$A$7:$F$7,0)),INDEX('ERP2020'!$A$166:$E$190,MATCH(CRP!$A13,'ERP2020'!$A$166:$A$190,0),MATCH($AC$2,'ERP2020'!$A$166:$E$166,0)))*100 -> 2.9095136 | X13: =IFERROR(INDEX('ERP2021'!$A$8:$F$165,MATCH(CRP!$A13,'ERP2021'!$A$8:$A$165,0),MATCH($AC$1,'ERP2021'!$A$7:$F$7,0)),INDEX('ERP2021'!$A$166:$E$190,MATCH(CRP!$A13,'ERP2021'!$A$166:$A$190,0),MATCH($AC$2,'ERP2021'!$A$166:$E$166,0)))*100 -> 3.5597338 | Y13: =IFERROR(INDEX('ERP2022'!$A$8:$F$165,MATCH(CRP!$A13,'ERP2022'!$A$8:$A$165,0),MATCH($AC$1,'ERP2022'!$A$7:$F$7,0)),INDEX('ERP2022'!$A$166:$E$190,MATCH(CRP!$A13,'ERP2022'!$A$166:$A$190,0),MATCH($AC$2,'ERP2022'!$A$166:$E$166,0)))*100 -> 7.7694679 | Z13: =IFERROR(INDEX('ERP2023'!$A$8:$F$165,MATCH(CRP!$A13,'ERP2023'!$A$8:$A$165,0),MATCH($AC$1,'ERP2023'!$A$7:$F$7,0)),INDEX('ERP2023'!$A$165:$E$190,MATCH(CRP!$A13,'ERP2023'!$A$165:$A$190,0),MATCH($AC$2,'ERP2023'!$A$165:$E$165,0)))*100 -> 6.5834727 | AA13: =IFERROR(INDEX('ERP2024'!$A$8:$F$165,MATCH(CRP!$A13,'ERP2024'!$A$8:$A$165,0),MATCH($AC$1,'ERP2024'!$A$7:$F$7,0)),INDEX('ERP2024'!$A$166:$E$190,MATCH(CRP!$A13,'ERP2024'!$A$166:$A$190,0),MATCH($AC$2,'ERP2024'!$A$166:$E$166,0)))*100 -> 6.0075264 | AB13: =IFERROR(INDEX('ERP2025'!$A$8:$F$165,MATCH(CRP!$A13,'ERP2025'!$A$8:$A$165,0),MATCH($AC$1,'ERP2025'!$A$7:$F$7,0)),INDEX('ERP2024'!$A$166:$E$190,MATCH(CRP!$A13,'ERP2025'!$A$166:$A$190,0),MATCH($AC$2,'ERP2024'!$A$166:$E$166,0)))*100 -> 6.659166
